Workbook

Sheet A.Y
A1: ANYELUZ | C1: ENERO | H1: FEBRERO | M1: MARZO | R1: ABRIL | W1: MAYO | AB1: JUNIO | AG1: JULIO | AL1: AGOSTO | AQ1: SEPTIEMBRE | AV1: OCTUBRE | BA1: NOVIEMBRE | BF1: DICIEMBRE | BK1: ENERO
A2: PRODUCTO | B2: VR. COMPRA | C2: INV.I | D2: Entra | E2: Saldo | F2: SALIDA | G2: TOTAL | H2: INV.I | I2: Entra | J2: Saldo | K2: SALIDA | L2: TOTAL | M2: INV.I | N2: Entra | O2: Saldo | P2: SALIDA | Q2: TOTAL | R2: INV.I | S2: Entra | T2: Saldo | U2: SALIDA | V2: TOTAL | W2: INV.I | X2: Entra | Y2: Saldo | Z2: SALIDA | AA2: TOTAL | AB2: INV.I | AC2: Entra | AD2: Saldo | AE2: SALIDA | AF2: TOTAL | AG2: INV.I | AH2: Entra | AI2: Saldo | AJ2: SALIDA | AK2: TOTAL | AL2: INV.I | AM2: Entra | AN2: Saldo | AO2: SALIDA | AP2: TOTAL | AQ2: INV.I | AR2: Entra | AS2: Saldo | AT2: SALIDA | AU2: TOTAL | AV2: INV.I | AW2: Entra | AX2: Saldo | AY2: SALIDA | AZ2: TOTAL | BA2: INV.I | BB2: Entra | BC2: Saldo | BD2: SALIDA | BE2: TOTAL | BF2: INV.I | BG2: Entra | BH2: Saldo | BI2: SALIDA | BJ2: TOTAL | BK2: INV.I
A3: SH. CEBOLLA | B3: 31500 | F3: =+E3-H3 -> 0 | G3: =((E3-F3)*$B3) -> 0 | K3: =+J3-M3 -> 0 | L3: =((J3-K3)*$B3) -> 0 | P3: =+O3-R3 -> 0 | Q3: =((O3-P3)*$B3) -> 0 | U3: =+T3-W3 -> 0 | V3: =((T3-U3)*$B3) -> 0 | Y3: =+W3+X3 -> 0 | Z3: =+Y3-AB3 -> 0 | AA3: =((Y3-Z3)*$B3) -> 0 | AD3: =+AB3+AC3 -> 0 | AE3: =+AD3-AG3 -> -13 | AF3: =((AD3-AE3)*$B3) -> 409500 | AG3: 13 | AI3: =+AG3+AH3 -> 13 | AJ3: =+AI3-AL3 -> 1 | AK3: =((AI3-AJ3)*$B3) -> 378000 | AL3: 12 | AN3: =+AL3+AM3 -> 12 | AO3: =+AN3-AQ3 -> 3 | AP3: =((AN3-AO3)*$B3) -> 283500 | AQ3: 9 | AS3: =AQ3+AR3 -> 9 | AT3: =+AS3-AV3 -> 9 | AU3: =((AS3-AT3)*$B3) -> 0 | AX3: =+AV3+AW3 -> 0 | AY3: =+AX3-BA3 -> 0 | AZ3: =((AX3-AY3)*$B3) -> 0 | BC3: =+BA3+BB3 -> 0 | BD3: =+BC3-BF3 -> 0 | BE3: =((BC3-BD3)*$B3) -> 0 | BH3: =+BF3+BG3 -> 0 | BI3: =+BH3-BK3 -> 0 | BJ3: =((BH3-BI3)*$B3) -> 0
A4: AC. CEBOLLA | B4: 28000 | F4: =+E4-H4 -> 0 | G4: =((E4-F4)*$B4) -> 0 | K4: =+J4-M4 -> 0 | L4: =((J4-K4)*$B4) -> 0 | P4: =+O4-R4 -> 0 | Q4: =((O4-P4)*$B4) -> 0 | U4: =+T4-W4 -> 0 | V4: =((T4-U4)*$B4) -> 0 | Y4: =+W4+X4 -> 0 | Z4: =+Y4-AB4 -> 0 | AA4: =((Y4-Z4)*$B4) -> 0 | AD4: =+AB4+AC4 -> 0 | AE4: =+AD4-AG4 -> -9 | AF4: =((AD4-AE4)*$B4) -> 252000 | AG4: 9 | AI4: =+AG4+AH4 -> 9 | AJ4: =+AI4-AL4 -> 1 | AK4: =((AI4-AJ4)*$B4) -> 224000 | AL4: 8 | AN4: =+AL4+AM4 -> 8 | AO4: =+AN4-AQ4 -> 2 | AP4: =((AN4-AO4)*$B4) -> 168000 | AQ4: 6 | AS4: =AQ4+AR4 -> 6 | AT4: =+AS4-AV4 -> 6 | AU4: =((AS4-AT4)*$B4) -> 0 | AX4: =+AV4+AW4 -> 0 | AY4: =+AX4-BA4 -> 0 | AZ4: =((AX4-AY4)*$B4) -> 0 | BC4: =+BA4+BB4 -> 0 | BD4: =+BC4-BF4 -> 0 | BE4: =((BC4-BD4)*$B4) -> 0 | BH4: =+BF4+BG4 -> 0 | BI4: =+BH4-BK4 -> 0 | BJ4: =((BH4-BI4)*$B4) -> 0
A5: SH. ROMERO | B5: 31500 | F5: =+E5-H5 -> 0 | G5: =((E5-F5)*$B5) -> 0 | K5: =+J5-M5 -> 0 | L5: =((J5-K5)*$B5) -> 0 | P5: =+O5-R5 -> 0 | Q5: =((O5-P5)*$B5) -> 0 | U5: =+T5-W5 -> 0 | V5: =((T5-U5)*$B5) -> 0 | Y5: =+W5+X5 -> 0 | Z5: =+Y5-AB5 -> 0 | AA5: =((Y5-Z5)*$B5) -> 0 | AD5: =+AB5+AC5 -> 0 | AE5: =+AD5-AG5 -> -6 | AF5: =((AD5-AE5)*$B5) -> 189000 | AG5: 6 | AI5: =+AG5+AH5 -> 6 | AJ5: =+AI5-AL5 -> 1 | AK5: =((AI5-AJ5)*$B5) -> 157500 | AL5: 5 | AN5: =+AL5+AM5 -> 5 | AO5: =+AN5-AQ5 -> 2 | AP5: =((AN5-AO5)*$B5) -> 94500 | AQ5: 3 | AS5: =AQ5+AR5 -> 3 | AT5: =+AS5-AV5 -> 3 | AU5: =((AS5-AT5)*$B5) -> 0 | AX5: =+AV5+AW5 -> 0 | AY5: =+AX5-BA5 -> 0 | AZ5: =((AX5-AY5)*$B5) -> 0 | BC5: =+BA5+BB5 -> 0 | BD5: =+BC5-BF5 -> 0 | BE5: =((BC5-BD5)*$B5) -> 0 | BH5: =+BF5+BG5 -> 0 | BI5: =+BH5-BK5 -> 0 | BJ5: =((BH5-BI5)*$B5) -> 0
A6: AC. ROMERO | B6: 28000 | F6: =+E6-H6 -> 0 | G6: =((E6-F6)*$B6) -> 0 | K6: =+J6-M6 -> 0 | L6: =((J6-K6)*$B6) -> 0 | P6: =+O6-R6 -> 0 | Q6: =((O6-P6)*$B6) -> 0 | U6: =+T6-W6 -> 0 | V6: =((T6-U6)*$B6) -> 0 | Y6: =+W6+X6 -> 0 | Z6: =+Y6-AB6 -> 0 | AA6: =((Y6-Z6)*$B6) -> 0 | AD6: =+AB6+AC6 -> 0 | AE6: =+AD6-AG6 -> -10 | AF6: =((AD6-AE6)*$B6) -> 280000 | AG6: 10 | AI6: =+AG6+AH6 -> 10 | AJ6: =+AI6-AL6 -> 1 | AK6: =((AI6-AJ6)*$B6) -> 252000 | AL6: 9 | AN6: =+AL6+AM6 -> 9 | AO6: =+AN6-AQ6 -> 3 | AP6: =((AN6-AO6)*$B6) -> 168000 | AQ6: 6 | AS6: =AQ6+AR6 -> 6 | AT6: =+AS6-AV6 -> 6 | AU6: =((AS6-AT6)*$B6) -> 0 | AX6: =+AV6+AW6 -> 0 | AY6: =+AX6-BA6 -> 0 | AZ6: =((AX6-AY6)*$B6) -> 0 | BC6: =+BA6+BB6 -> 0 | BD6: =+BC6-BF6 -> 0 | BE6: =((BC6-BD6)*$B6) -> 0 | BH6: =+BF6+BG6 -> 0 | BI6: =+BH6-BK6 -> 0 | BJ6: =((BH6-BI6)*$B6) -> 0
A7: SH. ANTI CASPA | B7: 28000 | F7: =+E7-H7 -> 0 | G7: =((E7-F7)*$B7) -> 0 | K7: =+J7-M7 -> 0 | L7: =((J7-K7)*$B7) -> 0 | P7: =+O7-R7 -> 0 | Q7: =((O7-P7)*$B7) -> 0 | U7: =+T7-W7 -> 0 | V7: =((T7-U7)*$B7) -> 0 | Y7: =+W7+X7 -> 0 | Z7: =+Y7-AB7 -> 0 | AA7: =((Y7-Z7)*$B7) -> 0 | AD7: =+AB7+AC7 -> 0 | AE7: =+AD7-AG7 -> -4 | AF7: =((AD7-AE7)*$B7) -> 112000 | AG7: 4 | AI7: =+AG7+AH7 -> 4 | AJ7: =+AI7-AL7 -> 0 | AK7: =((AI7-AJ7)*$B7) -> 112000 | AL7: 4 | AN7: =+AL7+AM7 -> 4 | AO7: =+AN7-AQ7 -> 1 | AP7: =((AN7-AO7)*$B7) -> 84000 | AQ7: 3 | AS7: =AQ7+AR7 -> 3 | AT7: =+AS7-AV7 -> 3 | AU7: =((AS7-AT7)*$B7) -> 0 | AX7: =+AV7+AW7 -> 0 | AY7: =+AX7-BA7 -> 0 | AZ7: =((AX7-AY7)*$B7) -> 0 | BC7: =+BA7+BB7 -> 0 | BD7: =+BC7-BF7 -> 0 | BE7: =((BC7-BD7)*$B7) -> 0 | BH7: =+BF7+BG7 -> 0 | BI7: =+BH7-BK7 -> 0 | BJ7: =((BH7-BI7)*$B7) -> 0
A8: SH. GUSANO DE SEDA | B8: 28000 | F8: =+E8-H8 -> 0 | G8: =((E8-F8)*$B8) -> 0 | K8: =+J8-M8 -> 0 | L8: =((J8-K8)*$B8) -> 0 | P8: =+O8-R8 -> 0 | Q8: =((O8-P8)*$B8) -> 0 | U8: =+T8-W8 -> 0 | V8: =((T8-U8)*$B8) -> 0 | Y8: =+W8+X8 -> 0 | Z8: =+Y8-AB8 -> 0 | AA8: =((Y8-Z8)*$B8) -> 0 | AD8: =+AB8+AC8 -> 0 | AE8: =+AD8-AG8 -> -12 | AF8: =((AD8-AE8)*$B8) -> 336000 | AG8: 12 | AI8: =+AG8+AH8 -> 12 | AJ8: =+AI8-AL8 -> 0 | AK8: =((AI8-AJ8)*$B8) -> 336000 | AL8: 12 | AN8: =+AL8+AM8 -> 12 | AO8: =+AN8-AQ8 -> 0 | AP8: =((AN8-AO8)*$B8) -> 336000 | AQ8: 12 | AS8: =AQ8+AR8 -> 12 | AT8: =+AS8-AV8 -> 12 | AU8: =((AS8-AT8)*$B8) -> 0 | AX8: =+AV8+AW8 -> 0 | AY8: =+AX8-BA8 -> 0 | AZ8: =((AX8-AY8)*$B8) -> 0 | BC8: =+BA8+BB8 -> 0 | BD8: =+BC8-BF8 -> 0 | BE8: =((BC8-BD8)*$B8) -> 0 | BH8: =+BF8+BG8 -> 0 | BI8: =+BH8-BK8 -> 0 | BJ8: =((BH8-BI8)*$B8) -> 0
A9: SH. ALOE VERA | B9: 28000 | F9: =+E9-H9 -> 0 | G9: =((E9-F9)*$B9) -> 0 | K9: =+J9-M9 -> 0 | L9: =((J9-K9)*$B9) -> 0 | P9: =+O9-R9 -> 0 | Q9: =((O9-P9)*$B9) -> 0 | U9: =+T9-W9 -> 0 | V9: =((T9-U9)*$B9) -> 0 | Y9: =+W9+X9 -> 0 | Z9: =+Y9-AB9 -> 0 | AA9: =((Y9-Z9)*$B9) -> 0 | AD9: =+AB9+AC9 -> 0 | AE9: =+AD9-AG9 -> -10 | AF9: =((AD9-AE9)*$B9) -> 280000 | AG9: 10 | AI9: =+AG9+AH9 -> 10 | AJ9: =+AI9-AL9 -> 0 | AK9: =((AI9-AJ9)*$B9) -> 280000 | AL9: 10 | AN9: =+AL9+AM9 -> 10 | AO9: =+AN9-AQ9 -> 0 | AP9: =((AN9-AO9)*$B9) -> 280000 | AQ9: 10 | AS9: =AQ9+AR9 -> 10 | AT9: =+AS9-AV9 -> 10 | AU9: =((AS9-AT9)*$B9) -> 0 | AX9: =+AV9+AW9 -> 0 | AY9: =+AX9-BA9 -> 0 | AZ9: =((AX9-AY9)*$B9) -> 0 | BC9: =+BA9+BB9 -> 0 | BD9: =+BC9-BF9 -> 0 | BE9: =((BC9-BD9)*$B9) -> 0 | BH9: =+BF9+BG9 -> 0 | BI9: =+BH9-BK9 -> 0 | BJ9: =((BH9-BI9)*$B9) -> 0
A10: COCTEL FRUTAS | B10: 35000 | F10: =+E10-H10 -> 0 | G10: =((E10-F10)*$B10) -> 0 | K10: =+J10-M10 -> 0 | L10: =((J10-K10)*$B10) -> 0 | P10: =+O10-R10 -> 0 | Q10: =((O10-P10)*$B10) -> 0 | U10: =+T10-W10 -> 0 | V10: =((T10-U10)*$B10) -> 0 | Y10: =+W10+X10 -> 0 | Z10: =+Y10-AB10 -> 0 | AA10: =((Y10-Z10)*$B10) -> 0 | AD10: =+AB10+AC10 -> 0 | AE10: =+AD10-AG10 -> -6 | AF10: =((AD10-AE10)*$B10) -> 210000 | AG10: 6 | AI10: =+AG10+AH10 -> 6 | AJ10: =+AI10-AL10 -> 1 | AK10: =((AI10-AJ10)*$B10) -> 175000 | AL10: 5 | AN10: =+AL10+AM10 -> 5 | AO10: =+AN10-AQ10 -> -1 | AP10: =((AN10-AO10)*$B10) -> 210000 | AQ10: 6 | AS10: =AQ10+AR10 -> 6 | AT10: =+AS10-AV10 -> 6 | AU10: =((AS10-AT10)*$B10) -> 0 | AX10: =+AV10+AW10 -> 0 | AY10: =+AX10-BA10 -> 0 | AZ10: =((AX10-AY10)*$B10) -> 0 | BC10: =+BA10+BB10 -> 0 | BD10: =+BC10-BF10 -> 0 | BE10: =((BC10-BD10)*$B10) -> 0 | BH10: =+BF10+BG10 -> 0 | BI10: =+BH10-BK10 -> 0 | BJ10: =((BH10-BI10)*$B10) -> 0
A11: AC. ARGÁN | B11: 28000 | F11: =+E11-H11 -> 0 | G11: =((E11-F11)*$B11) -> 0 | K11: =+J11-M11 -> 0 | L11: =((J11-K11)*$B11) -> 0 | P11: =+O11-R11 -> 0 | Q11: =((O11-P11)*$B11) -> 0 | U11: =+T11-W11 -> 0 | V11: =((T11-U11)*$B11) -> 0 | Y11: =+W11+X11 -> 0 | Z11: =+Y11-AB11 -> 0 | AA11: =((Y11-Z11)*$B11) -> 0 | AD11: =+AB11+AC11 -> 0 | AE11: =+AD11-AG11 -> -6 | AF11: =((AD11-AE11)*$B11) -> 168000 | AG11: 6 | AI11: =+AG11+AH11 -> 6 | AJ11: =+AI11-AL11 -> 0 | AK11: =((AI11-AJ11)*$B11) -> 168000 | AL11: 6 | AN11: =+AL11+AM11 -> 6 | AO11: =+AN11-AQ11 -> 3 | AP11: =((AN11-AO11)*$B11) -> 84000 | AQ11: 3 | AS11: =AQ11+AR11 -> 3 | AT11: =+AS11-AV11 -> 3 | AU11: =((AS11-AT11)*$B11) -> 0 | AX11: =+AV11+AW11 -> 0 | AY11: =+AX11-BA11 -> 0 | AZ11: =((AX11-AY11)*$B11) -> 0 | BC11: =+BA11+BB11 -> 0 | BD11: =+BC11-BF11 -> 0 | BE11: =((BC11-BD11)*$B11) -> 0 | BH11: =+BF11+BG11 -> 0 | BI11: =+BH11-BK11 -> 0 | BJ11: =((BH11-BI11)*$B11) -> 0
A12: SH. AGUACATE | B12: 28000 | F12: =+E12-H12 -> 0 | G12: =((E12-F12)*$B12) -> 0 | K12: =+J12-M12 -> 0 | L12: =((J12-K12)*$B12) -> 0 | P12: =+O12-R12 -> 0 | Q12: =((O12-P12)*$B12) -> 0 | U12: =+T12-W12 -> 0 | V12: =((T12-U12)*$B12) -> 0 | Y12: =+W12+X12 -> 0 | Z12: =+Y12-AB12 -> 0 | AA12: =((Y12-Z12)*$B12) -> 0 | AD12: =+AB12+AC12 -> 0 | AE12: =+AD12-AG12 -> -3 | AF12: =((AD12-AE12)*$B12) -> 84000 | AG12: 3 | AI12: =+AG12+AH12 -> 3 | AJ12: =+AI12-AL12 -> 0 | AK12: =((AI12-AJ12)*$B12) -> 84000 | AL12: 3 | AN12: =+AL12+AM12 -> 3 | AO12: =+AN12-AQ12 -> 1 | AP12: =((AN12-AO12)*$B12) -> 56000 | AQ12: 2 | AS12: =AQ12+AR12 -> 2 | AT12: =+AS12-AV12 -> 2 | AU12: =((AS12-AT12)*$B12) -> 0 | AX12: =+AV12+AW12 -> 0 | AY12: =+AX12-BA12 -> 0 | AZ12: =((AX12-AY12)*$B12) -> 0 | BC12: =+BA12+BB12 -> 0 | BD12: =+BC12-BF12 -> 0 | BE12: =((BC12-BD12)*$B12) -> 0 | BH12: =+BF12+BG12 -> 0 | BI12: =+BH12-BK12 -> 0 | BJ12: =((BH12-BI12)*$B12) -> 0
A13: SH. BANANO | B13: 28000 | F13: =+E13-H13 -> 0 | G13: =((E13-F13)*$B13) -> 0 | K13: =+J13-M13 -> 0 | L13: =((J13-K13)*$B13) -> 0 | P13: =+O13-R13 -> 0 | Q13: =((O13-P13)*$B13) -> 0 | U13: =+T13-W13 -> 0 | V13: =((T13-U13)*$B13) -> 0 | Y13: =+W13+X13 -> 0 | Z13: =+Y13-AB13 -> 0 | AA13: =((Y13-Z13)*$B13) -> 0 | AD13: =+AB13+AC13 -> 0 | AE13: =+AD13-AG13 -> -3 | AF13: =((AD13-AE13)*$B13) -> 84000 | AG13: 3 | AI13: =+AG13+AH13 -> 3 | AJ13: =+AI13-AL13 -> 1 | AK13: =((AI13-AJ13)*$B13) -> 56000 | AL13: 2 | AM13: 4 | AN13: =+AL13+AM13 -> 6 | AO13: =+AN13-AQ13 -> 0 | AP13: =((AN13-AO13)*$B13) -> 168000 | AQ13: 6 | AS13: =AQ13+AR13 -> 6 | AT13: =+AS13-AV13 -> 6 | AU13: =((AS13-AT13)*$B13) -> 0 | AX13: =+AV13+AW13 -> 0 | AY13: =+AX13-BA13 -> 0 | AZ13: =((AX13-AY13)*$B13) -> 0 | BC13: =+BA13+BB13 -> 0 | BD13: =+BC13-BF13 -> 0 | BE13: =((BC13-BD13)*$B13) -> 0 | BH13: =+BF13+BG13 -> 0 | BI13: =+BH13-BK13 -> 0 | BJ13: =((BH13-BI13)*$B13) -> 0
A14: AC. BANANO | B14: 28000 | F14: =+E14-H14 -> 0 | G14: =((E14-F14)*$B14) -> 0 | K14: =+J14-M14 -> 0 | L14: =((J14-K14)*$B14) -> 0 | P14: =+O14-R14 -> 0 | Q14: =((O14-P14)*$B14) -> 0 | U14: =+T14-W14 -> 0 | V14: =((T14-U14)*$B14) -> 0 | Y14: =+W14+X14 -> 0 | Z14: =+Y14-AB14 -> 0 | AA14: =((Y14-Z14)*$B14) -> 0 | AD14: =+AB14+AC14 -> 0 | AE14: =+AD14-AG14 -> -2 | AF14: =((AD14-AE14)*$B14) -> 56000 | AG14: 2 | AI14: =+AG14+AH14 -> 2 | AJ14: =+AI14-AL14 -> 0 | AK14: =((AI14-AJ14)*$B14) -> 56000 | AL14: 2 | AN14: =+AL14+AM14 -> 2 | AO14: =+AN14-AQ14 -> 1 | AP14: =((AN14-AO14)*$B14) -> 28000 | AQ14: 1 | AS14: =AQ14+AR14 -> 1 | AT14: =+AS14-AV14 -> 1 | AU14: =((AS14-AT14)*$B14) -> 0 | AX14: =+AV14+AW14 -> 0 | AY14: =+AX14-BA14 -> 0 | AZ14: =((AX14-AY14)*$B14) -> 0 | BC14: =+BA14+BB14 -> 0 | BD14: =+BC14-BF14 -> 0 | BE14: =((BC14-BD14)*$B14) -> 0 | BH14: =+BF14+BG14 -> 0 | BI14: =+BH14-BK14 -> 0 | BJ14: =((BH14-BI14)*$B14) -> 0
A15: MASCARILLA NUTRITIVA DE BANANO | B15: 30100 | F15: =+E15-H15 -> 0 | G15: =((E15-F15)*$B15) -> 0 | K15: =+J15-M15 -> 0 | L15: =((J15-K15)*$B15) -> 0 | P15: =+O15-R15 -> 0 | Q15: =((O15-P15)*$B15) -> 0 | U15: =+T15-W15 -> 0 | V15: =((T15-U15)*$B15) -> 0 | Y15: =+W15+X15 -> 0 | Z15: =+Y15-AB15 -> 0 | AA15: =((Y15-Z15)*$B15) -> 0 | AD15: =+AB15+AC15 -> 0 | AE15: =+AD15-AG15 -> -3 | AF15: =((AD15-AE15)*$B15) -> 90300 | AG15: 3 | AI15: =+AG15+AH15 -> 3 | AJ15: =+AI15-AL15 -> 0 | AK15: =((AI15-AJ15)*$B15) -> 90300 | AL15: 3 | AN15: =+AL15+AM15 -> 3 | AO15: =+AN15-AQ15 -> 1 | AP15: =((AN15-AO15)*$B15) -> 60200 | AQ15: 2 | AS15: =AQ15+AR15 -> 2 | AT15: =+AS15-AV15 -> 2 | AU15: =((AS15-AT15)*$B15) -> 0 | AX15: =+AV15+AW15 -> 0 | AY15: =+AX15-BA15 -> 0 | AZ15: =((AX15-AY15)*$B15) -> 0 | BC15: =+BA15+BB15 -> 0 | BD15: =+BC15-BF15 -> 0 | BE15: =((BC15-BD15)*$B15) -> 0 | BH15: =+BF15+BG15 -> 0 | BI15: =+BH15-BK15 -> 0 | BJ15: =((BH15-BI15)*$B15) -> 0
A16: TERAPIA CAPILAR DE CEBOLLA | B16: 32200 | F16: =+E16-H16 -> 0 | G16: =((E16-F16)*$B16) -> 0 | K16: =+J16-M16 -> 0 | L16: =((J16-K16)*$B16) -> 0 | P16: =+O16-R16 -> 0 | Q16: =((O16-P16)*$B16) -> 0 | U16: =+T16-W16 -> 0 | V16: =((T16-U16)*$B16) -> 0 | Y16: =+W16+X16 -> 0 | Z16: =+Y16-AB16 -> 0 | AA16: =((Y16-Z16)*$B16) -> 0 | AD16: =+AB16+AC16 -> 0 | AE16: =+AD16-AG16 -> -12 | AF16: =((AD16-AE16)*$B16) -> 386400 | AG16: 12 | AI16: =+AG16+AH16 -> 12 | AJ16: =+AI16-AL16 -> 0 | AK16: =((AI16-AJ16)*$B16) -> 386400 | AL16: 12 | AN16: =+AL16+AM16 -> 12 | AO16: =+AN16-AQ16 -> 0 | AP16: =((AN16-AO16)*$B16) -> 386400 | AQ16: 12 | AS16: =AQ16+AR16 -> 12 | AT16: =+AS16-AV16 -> 12 | AU16: =((AS16-AT16)*$B16) -> 0 | AX16: =+AV16+AW16 -> 0 | AY16: =+AX16-BA16 -> 0 | AZ16: =((AX16-AY16)*$B16) -> 0 | BC16: =+BA16+BB16 -> 0 | BD16: =+BC16-BF16 -> 0 | BE16: =((BC16-BD16)*$B16) -> 0 | BH16: =+BF16+BG16 -> 0 | BI16: =+BH16-BK16 -> 0 | BJ16: =((BH16-BI16)*$B16) -> 0
A17: TRATAMIENTO NUTRITIVO | B17: 31500 | F17: =+E17-H17 -> 0 | G17: =((E17-F17)*$B17) -> 0 | K17: =+J17-M17 -> 0 | L17: =((J17-K17)*$B17) -> 0 | P17: =+O17-R17 -> 0 | Q17: =((O17-P17)*$B17) -> 0 | U17: =+T17-W17 -> 0 | V17: =((T17-U17)*$B17) -> 0 | Y17: =+W17+X17 -> 0 | Z17: =+Y17-AB17 -> 0 | AA17: =((Y17-Z17)*$B17) -> 0 | AD17: =+AB17+AC17 -> 0 | AE17: =+AD17-AG17 -> 0 | AF17: =((AD17-AE17)*$B17) -> 0 | AG17: 0 | AI17: =+AG17+AH17 -> 0 | AJ17: =+AI17-AL17 -> 0 | AK17: =((AI17-AJ17)*$B17) -> 0 | AL17: 0 | AM17: 6 | AN17: =+AL17+AM17 -> 6 | AO17: =+AN17-AQ17 -> 0 | AP17: =((AN17-AO17)*$B17) -> 189000 | AQ17: 6 | AS17: =AQ17+AR17 -> 6 | AT17: =+AS17-AV17 -> 6 | AU17: =((AS17-AT17)*$B17) -> 0 | AX17: =+AV17+AW17 -> 0 | AY17: =+AX17-BA17 -> 0 | AZ17: =((AX17-AY17)*$B17) -> 0 | BC17: =+BA17+BB17 -> 0 | BD17: =+BC17-BF17 -> 0 | BE17: =((BC17-BD17)*$B17) -> 0 | BH17: =+BF17+BG17 -> 0 | BI17: =+BH17-BK17 -> 0 | BJ17: =((BH17-BI17)*$B17) -> 0
A18: BIOTERAPIA CAPILAR | B18: 30100 | F18: =+E18-H18 -> 0 | G18: =((E18-F18)*$B18) -> 0 | K18: =+J18-M18 -> 0 | L18: =((J18-K18)*$B18) -> 0 | P18: =+O18-R18 -> 0 | Q18: =((O18-P18)*$B18) -> 0 | U18: =+T18-W18 -> 0 | V18: =((T18-U18)*$B18) -> 0 | Y18: =+W18+X18 -> 0 | Z18: =+Y18-AB18 -> 0 | AA18: =((Y18-Z18)*$B18) -> 0 | AD18: =+AB18+AC18 -> 0 | AE18: =+AD18-AG18 -> -4 | AF18: =((AD18-AE18)*$B18) -> 120400 | AG18: 4 | AI18: =+AG18+AH18 -> 4 | AJ18: =+AI18-AL18 -> 2 | AK18: =((AI18-AJ18)*$B18) -> 60200 | AL18: 2 | AN18: =+AL18+AM18 -> 2 | AO18: =+AN18-AQ18 -> -1 | AP18: =((AN18-AO18)*$B18) -> 90300 | AQ18: 3 | AS18: =AQ18+AR18 -> 3 | AT18: =+AS18-AV18 -> 3 | AU18: =((AS18-AT18)*$B18) -> 0 | AX18: =+AV18+AW18 -> 0 | AY18: =+AX18-BA18 -> 0 | AZ18: =((AX18-AY18)*$B18) -> 0 | BC18: =+BA18+BB18 -> 0 | BD18: =+BC18-BF18 -> 0 | BE18: =((BC18-BD18)*$B18) -> 0 | BH18: =+BF18+BG18 -> 0 | BI18: =+BH18-BK18 -> 0 | BJ18: =((BH18-BI18)*$B18) -> 0
A19: GEL ANTICELULITICO | B19: 26600 | F19: =+E19-H19 -> 0 | G19: =((E19-F19)*$B19) -> 0 | K19: =+J19-M19 -> 0 | L19: =((J19-K19)*$B19) -> 0 | P19: =+O19-R19 -> 0 | Q19: =((O19-P19)*$B19) -> 0 | U19: =+T19-W19 -> 0 | V19: =((T19-U19)*$B19) -> 0 | Y19: =+W19+X19 -> 0 | Z19: =+Y19-AB19 -> 0 | AA19: =((Y19-Z19)*$B19) -> 0 | AD19: =+AB19+AC19 -> 0 | AE19: =+AD19-AG19 -> -2 | AF19: =((AD19-AE19)*$B19) -> 53200 | AG19: 2 | AI19: =+AG19+AH19 -> 2 | AJ19: =+AI19-AL19 -> 1 | AK19: =((AI19-AJ19)*$B19) -> 26600 | AL19: 1 | AN19: =+AL19+AM19 -> 1 | AO19: =+AN19-AQ19 -> 0 | AP19: =((AN19-AO19)*$B19) -> 26600 | AQ19: 1 | AS19: =AQ19+AR19 -> 1 | AT19: =+AS19-AV19 -> 1 | AU19: =((AS19-AT19)*$B19) -> 0 | AX19: =+AV19+AW19 -> 0 | AY19: =+AX19-BA19 -> 0 | AZ19: =((AX19-AY19)*$B19) -> 0 | BC19: =+BA19+BB19 -> 0 | BD19: =+BC19-BF19 -> 0 | BE19: =((BC19-BD19)*$B19) -> 0 | BH19: =+BF19+BG19 -> 0 | BI19: =+BH19-BK19 -> 0 | BJ19: =((BH19-BI19)*$B19) -> 0
A20: POTENCIALIZADOR DE ROMERO | B20: 31500 | F20: =+E20-H20 -> 0 | G20: =((E20-F20)*$B20) -> 0 | K20: =+J20-M20 -> 0 | L20: =((J20-K20)*$B20) -> 0 | P20: =+O20-R20 -> 0 | Q20: =((O20-P20)*$B20) -> 0 | U20: =+T20-W20 -> 0 | V20: =((T20-U20)*$B20) -> 0 | Y20: =+W20+X20 -> 0 | Z20: =+Y20-AB20 -> 0 | AA20: =((Y20-Z20)*$B20) -> 0 | AD20: =+AB20+AC20 -> 0 | AE20: =+AD20-AG20 -> -5 | AF20: =((AD20-AE20)*$B20) -> 157500 | AG20: 5 | AI20: =+AG20+AH20 -> 5 | AJ20: =+AI20-AL20 -> 0 | AK20: =((AI20-AJ20)*$B20) -> 157500 | AL20: 5 | AN20: =+AL20+AM20 -> 5 | AO20: =+AN20-AQ20 -> 0 | AP20: =((AN20-AO20)*$B20) -> 157500 | AQ20: 5 | AS20: =AQ20+AR20 -> 5 | AT20: =+AS20-AV20 -> 5 | AU20: =((AS20-AT20)*$B20) -> 0 | AX20: =+AV20+AW20 -> 0 | AY20: =+AX20-BA20 -> 0 | AZ20: =((AX20-AY20)*$B20) -> 0 | BC20: =+BA20+BB20 -> 0 | BD20: =+BC20-BF20 -> 0 | BE20: =((BC20-BD20)*$B20) -> 0 | BH20: =+BF20+BG20 -> 0 | BI20: =+BH20-BK20 -> 0 | BJ20: =((BH20-BI20)*$B20) -> 0
A21: ÓLEO ANTIEDAD | B21: 49000 | F21: =+E21-H21 -> 0 | G21: =((E21-F21)*$B21) -> 0 | K21: =+J21-M21 -> 0 | L21: =((J21-K21)*$B21) -> 0 | P21: =+O21-R21 -> 0 | Q21: =((O21-P21)*$B21) -> 0 | U21: =+T21-W21 -> 0 | V21: =((T21-U21)*$B21) -> 0 | Y21: =+W21+X21 -> 0 | Z21: =+Y21-AB21 -> 0 | AA21: =((Y21-Z21)*$B21) -> 0 | AD21: =+AB21+AC21 -> 0 | AE21: =+AD21-AG21 -> -2 | AF21: =((AD21-AE21)*$B21) -> 98000 | AG21: 2 | AI21: =+AG21+AH21 -> 2 | AJ21: =+AI21-AL21 -> 0 | AK21: =((AI21-AJ21)*$B21) -> 98000 | AL21: 2 | AN21: =+AL21+AM21 -> 2 | AO21: =+AN21-AQ21 -> 0 | AP21: =((AN21-AO21)*$B21) -> 98000 | AQ21: 2 | AS21: =AQ21+AR21 -> 2 | AT21: =+AS21-AV21 -> 2 | AU21: =((AS21-AT21)*$B21) -> 0 | AX21: =+AV21+AW21 -> 0 | AY21: =+AX21-BA21 -> 0 | AZ21: =((AX21-AY21)*$B21) -> 0 | BC21: =+BA21+BB21 -> 0 | BD21: =+BC21-BF21 -> 0 | BE21: =((BC21-BD21)*$B21) -> 0 | BH21: =+BF21+BG21 -> 0 | BI21: =+BH21-BK21 -> 0 | BJ21: =((BH21-BI21)*$B21) -> 0
A22: TÓNICO ANTICAÍDA DE CEBOLLA | B22: 49000 | F22: =+E22-H22 -> 0 | G22: =((E22-F22)*$B22) -> 0 | K22: =+J22-M22 -> 0 | L22: =((J22-K22)*$B22) -> 0 | P22: =+O22-R22 -> 0 | Q22: =((O22-P22)*$B22) -> 0 | U22: =+T22-W22 -> 0 | V22: =((T22-U22)*$B22) -> 0 | Y22: =+W22+X22 -> 0 | Z22: =+Y22-AB22 -> 0 | AA22: =((Y22-Z22)*$B22) -> 0 | AD22: =+AB22+AC22 -> 0 | AE22: =+AD22-AG22 -> -3 | AF22: =((AD22-AE22)*$B22) -> 147000 | AG22: 3 | AI22: =+AG22+AH22 -> 3 | AJ22: =+AI22-AL22 -> 0 | AK22: =((AI22-AJ22)*$B22) -> 147000 | AL22: 3 | AN22: =+AL22+AM22 -> 3 | AO22: =+AN22-AQ22 -> 1 | AP22: =((AN22-AO22)*$B22) -> 98000 | AQ22: 2 | AS22: =AQ22+AR22 -> 2 | AT22: =+AS22-AV22 -> 2 | AU22: =((AS22-AT22)*$B22) -> 0 | AX22: =+AV22+AW22 -> 0 | AY22: =+AX22-BA22 -> 0 | AZ22: =((AX22-AY22)*$B22) -> 0 | BC22: =+BA22+BB22 -> 0 | BD22: =+BC22-BF22 -> 0 | BE22: =((BC22-BD22)*$B22) -> 0 | BH22: =+BF22+BG22 -> 0 | BI22: =+BH22-BK22 -> 0 | BJ22: =((BH22-BI22)*$B22) -> 0
A23: ÓLEO DE ARGÁN | B23: 49000 | F23: =+E23-H23 -> 0 | G23: =((E23-F23)*$B23) -> 0 | K23: =+J23-M23 -> 0 | L23: =((J23-K23)*$B23) -> 0 | P23: =+O23-R23 -> 0 | Q23: =((O23-P23)*$B23) -> 0 | U23: =+T23-W23 -> 0 | V23: =((T23-U23)*$B23) -> 0 | Y23: =+W23+X23 -> 0 | Z23: =+Y23-AB23 -> 0 | AA23: =((Y23-Z23)*$B23) -> 0 | AD23: =+AB23+AC23 -> 0 | AE23: =+AD23-AG23 -> -2 | AF23: =((AD23-AE23)*$B23) -> 98000 | AG23: 2 | AI23: =+AG23+AH23 -> 2 | AJ23: =+AI23-AL23 -> 1 | AK23: =((AI23-AJ23)*$B23) -> 49000 | AL23: 1 | AN23: =+AL23+AM23 -> 1 | AO23: =+AN23-AQ23 -> 0 | AP23: =((AN23-AO23)*$B23) -> 49000 | AQ23: 1 | AS23: =AQ23+AR23 -> 1 | AT23: =+AS23-AV23 -> 1 | AU23: =((AS23-AT23)*$B23) -> 0 | AX23: =+AV23+AW23 -> 0 | AY23: =+AX23-BA23 -> 0 | AZ23: =((AX23-AY23)*$B23) -> 0 | BC23: =+BA23+BB23 -> 0 | BD23: =+BC23-BF23 -> 0 | BE23: =((BC23-BD23)*$B23) -> 0 | BH23: =+BF23+BG23 -> 0 | BI23: =+BH23-BK23 -> 0 | BJ23: =((BH23-BI23)*$B23) -> 0
A24: CREMA PARA PEINAR COCO | B24: 26600 | F24: =+E24-H24 -> 0 | G24: =((E24-F24)*$B24) -> 0 | K24: =+J24-M24 -> 0 | L24: =((J24-K24)*$B24) -> 0 | P24: =+O24-R24 -> 0 | Q24: =((O24-P24)*$B24) -> 0 | U24: =+T24-W24 -> 0 | V24: =((T24-U24)*$B24) -> 0 | Y24: =+W24+X24 -> 0 | Z24: =+Y24-AB24 -> 0 | AA24: =((Y24-Z24)*$B24) -> 0 | AD24: =+AB24+AC24 -> 0 | AE24: =+AD24-AG24 -> 0 | AF24: =((AD24-AE24)*$B24) -> 0 | AG24: 0 | AI24: =+AG24+AH24 -> 0 | AJ24: =+AI24-AL24 -> 0 | AK24: =((AI24-AJ24)*$B24) -> 0 | AL24: 0 | AN24: =+AL24+AM24 -> 0 | AO24: =+AN24-AQ24 -> 0 | AP24: =((AN24-AO24)*$B24) -> 0 | AQ24: 0 | AS24: =AQ24+AR24 -> 0 | AT24: =+AS24-AV24 -> 0 | AU24: =((AS24-AT24)*$B24) -> 0 | AX24: =+AV24+AW24 -> 0 | AY24: =+AX24-BA24 -> 0 | AZ24: =((AX24-AY24)*$B24) -> 0 | BC24: =+BA24+BB24 -> 0 | BD24: =+BC24-BF24 -> 0 | BE24: =((BC24-BD24)*$B24) -> 0 | BH24: =+BF24+BG24 -> 0 | BI24: =+BH24-BK24 -> 0 | BJ24: =((BH24-BI24)*$B24) -> 0
A25: BLINDAGEM TERMOPROTECTOR | B25: 33600 | F25: =+E25-H25 -> 0 | G25: =((E25-F25)*$B25) -> 0 | K25: =+J25-M25 -> 0 | L25: =((J25-K25)*$B25) -> 0 | P25: =+O25-R25 -> 0 | Q25: =((O25-P25)*$B25) -> 0 | U25: =+T25-W25 -> 0 | V25: =((T25-U25)*$B25) -> 0 | Y25: =+W25+X25 -> 0 | Z25: =+Y25-AB25 -> 0 | AA25: =((Y25-Z25)*$B25) -> 0 | AD25: =+AB25+AC25 -> 0 | AE25: =+AD25-AG25 -> -1 | AF25: =((AD25-AE25)*$B25) -> 33600 | AG25: 1 | AI25: =+AG25+AH25 -> 1 | AJ25: =+AI25-AL25 -> 0 | AK25: =((AI25-AJ25)*$B25) -> 33600 | AL25: 1 | AN25: =+AL25+AM25 -> 1 | AO25: =+AN25-AQ25 -> 0 | AP25: =((AN25-AO25)*$B25) -> 33600 | AQ25: 1 | AS25: =AQ25+AR25 -> 1 | AT25: =+AS25-AV25 -> 1 | AU25: =((AS25-AT25)*$B25) -> 0 | AX25: =+AV25+AW25 -> 0 | AY25: =+AX25-BA25 -> 0 | AZ25: =((AX25-AY25)*$B25) -> 0 | BC25: =+BA25+BB25 -> 0 | BD25: =+BC25-BF25 -> 0 | BE25: =((BC25-BD25)*$B25) -> 0 | BH25: =+BF25+BG25 -> 0 | BI25: =+BH25-BK25 -> 0 | BJ25: =((BH25-BI25)*$B25) -> 0
A26: VITAMINA C DÍA | B26: 42000 | F26: =+E26-H26 -> 0 | G26: =((E26-F26)*$B26) -> 0 | K26: =+J26-M26 -> 0 | L26: =((J26-K26)*$B26) -> 0 | P26: =+O26-R26 -> 0 | Q26: =((O26-P26)*$B26) -> 0 | U26: =+T26-W26 -> 0 | V26: =((T26-U26)*$B26) -> 0 | Y26: =+W26+X26 -> 0 | Z26: =+Y26-AB26 -> 0 | AA26: =((Y26-Z26)*$B26) -> 0 | AD26: =+AB26+AC26 -> 0 | AE26: =+AD26-AG26 -> 0 | AF26: =((AD26-AE26)*$B26) -> 0 | AG26: 0 | AI26: =+AG26+AH26 -> 0 | AJ26: =+AI26-AL26 -> 0 | AK26: =((AI26-AJ26)*$B26) -> 0 | AL26: 0 | AN26: =+AL26+AM26 -> 0 | AO26: =+AN26-AQ26 -> 0 | AP26: =((AN26-AO26)*$B26) -> 0 | AQ26: 0 | AS26: =AQ26+AR26 -> 0 | AT26: =+AS26-AV26 -> 0 | AU26: =((AS26-AT26)*$B26) -> 0 | AX26: =+AV26+AW26 -> 0 | AY26: =+AX26-BA26 -> 0 | AZ26: =((AX26-AY26)*$B26) -> 0 | BC26: =+BA26+BB26 -> 0 | BD26: =+BC26-BF26 -> 0 | BE26: =((BC26-BD26)*$B26) -> 0 | BH26: =+BF26+BG26 -> 0 | BI26: =+BH26-BK26 -> 0 | BJ26: =((BH26-BI26)*$B26) -> 0
A27: VITAMINA C NOCHE | B27: 49000 | F27: =+E27-H27 -> 0 | G27: =((E27-F27)*$B27) -> 0 | K27: =+J27-M27 -> 0 | L27: =((J27-K27)*$B27) -> 0 | P27: =+O27-R27 -> 0 | Q27: =((O27-P27)*$B27) -> 0 | U27: =+T27-W27 -> 0 | V27: =((T27-U27)*$B27) -> 0 | Y27: =+W27+X27 -> 0 | Z27: =+Y27-AB27 -> 0 | AA27: =((Y27-Z27)*$B27) -> 0 | AD27: =+AB27+AC27 -> 0 | AE27: =+AD27-AG27 -> 0 | AF27: =((AD27-AE27)*$B27) -> 0 | AG27: 0 | AI27: =+AG27+AH27 -> 0 | AJ27: =+AI27-AL27 -> 0 | AK27: =((AI27-AJ27)*$B27) -> 0 | AL27: 0 | AN27: =+AL27+AM27 -> 0 | AO27: =+AN27-AQ27 -> 0 | AP27: =((AN27-AO27)*$B27) -> 0 | AQ27: 0 | AS27: =AQ27+AR27 -> 0 | AT27: =+AS27-AV27 -> 0 | AU27: =((AS27-AT27)*$B27) -> 0 | AX27: =+AV27+AW27 -> 0 | AY27: 0 | AZ27: =((AX27-AY27)*$B27) -> 0 | BC27: =+BA27+BB27 -> 0 | BD27: =+BC27-BF27 -> 0 | BE27: =((BC27-BD27)*$B27) -> 0 | BH27: =+BF27+BG27 -> 0 | BI27: =+BH27-BK27 -> 0 | BJ27: =((BH27-BI27)*$B27) -> 0
A28: CREMA HUMECTANTE Y REAFIRMANTE | B28: 26600 | F28: =+E28-H28 -> 0 | G28: =((E28-F28)*$B28) -> 0 | K28: =+J28-M28 -> 0 | L28: =((J28-K28)*$B28) -> 0 | P28: =+O28-R28 -> 0 | Q28: =((O28-P28)*$B28) -> 0 | U28: =+T28-W28 -> 0 | V28: =((T28-U28)*$B28) -> 0 | Y28: =+W28+X28 -> 0 | Z28: =+Y28-AB28 -> 0 | AA28: =((Y28-Z28)*$B28) -> 0 | AD28: =+AB28+AC28 -> 0 | AE28: =+AD28-AG28 -> -3 | AF28: =((AD28-AE28)*$B28) -> 79800 | AG28: 3 | AI28: =+AG28+AH28 -> 3 | AJ28: =+AI28-AL28 -> 0 | AK28: =((AI28-AJ28)*$B28) -> 79800 | AL28: 3 | AN28: =+AL28+AM28 -> 3 | AO28: =+AN28-AQ28 -> 0 | AP28: =((AN28-AO28)*$B28) -> 79800 | AQ28: 3 | AS28: =AQ28+AR28 -> 3 | AT28: =+AS28-AV28 -> 3 | AU28: =((AS28-AT28)*$B28) -> 0 | AX28: =+AV28+AW28 -> 0 | AY28: =+AX28-BA28 -> 0 | AZ28: =((AX28-AY28)*$B28) -> 0 | BC28: =+BA28+BB28 -> 0 | BD28: =+BC28-BF28 -> 0 | BE28: =((BC28-BD28)*$B28) -> 0 | BH28: =+BF28+BG28 -> 0 | BI28: =+BH28-BK28 -> 0 | BJ28: =((BH28-BI28)*$B28) -> 0
A29: PERFUME DE ROSAS | B29: 87500 | F29: =+E29-H29 -> 0 | G29: =((E29-F29)*$B29) -> 0 | K29: =+J29-M29 -> 0 | L29: =((J29-K29)*$B29) -> 0 | P29: =+O29-R29 -> 0 | Q29: =((O29-P29)*$B29) -> 0 | U29: =+T29-W29 -> 0 | V29: =((T29-U29)*$B29) -> 0 | Y29: =+W29+X29 -> 0 | Z29: =+Y29-AB29 -> 0 | AA29: =((Y29-Z29)*$B29) -> 0 | AD29: =+AB29+AC29 -> 0 | AE29: =+AD29-AG29 -> -1 | AF29: =((AD29-AE29)*$B29) -> 87500 | AG29: 1 | AI29: =+AG29+AH29 -> 1 | AJ29: =+AI29-AL29 -> 0 | AK29: =((AI29-AJ29)*$B29) -> 87500 | AL29: 1 | AN29: =+AL29+AM29 -> 1 | AO29: =+AN29-AQ29 -> 0 | AP29: =((AN29-AO29)*$B29) -> 87500 | AQ29: 1 | AS29: =AQ29+AR29 -> 1 | AT29: =+AS29-AV29 -> 1 | AU29: =((AS29-AT29)*$B29) -> 0 | AX29: =+AV29+AW29 -> 0 | AY29: =+AX29-BA29 -> 0 | AZ29: =((AX29-AY29)*$B29) -> 0 | BC29: =+BA29+BB29 -> 0 | BD29: =+BC29-BF29 -> 0 | BE29: =((BC29-BD29)*$B29) -> 0 | BH29: =+BF29+BG29 -> 0 | BI29: =+BH29-BK29 -> 0 | BJ29: =((BH29-BI29)*$B29) -> 0
A30: BRONCEADOR ACHIOTE / CANELA | B30: 29400 | F30: =+E30-H30 -> 0 | G30: =((E30-F30)*$B30) -> 0 | K30: =+J30-M30 -> 0 | L30: =((J30-K30)*$B30) -> 0 | P30: =+O30-R30 -> 0 | Q30: =((O30-P30)*$B30) -> 0 | U30: =+T30-W30 -> 0 | V30: =((T30-U30)*$B30) -> 0 | Y30: =+W30+X30 -> 0 | Z30: =+Y30-AB30 -> 0 | AA30: =((Y30-Z30)*$B30) -> 0 | AD30: =+AB30+AC30 -> 0 | AE30: =+AD30-AG30 -> -9 | AF30: =((AD30-AE30)*$B30) -> 264600 | AG30: 9 | AI30: =+AG30+AH30 -> 9 | AJ30: =+AI30-AL30 -> 0 | AK30: =((AI30-AJ30)*$B30) -> 264600 | AL30: 9 | AN30: =+AL30+AM30 -> 9 | AO30: =+AN30-AQ30 -> 0 | AP30: =((AN30-AO30)*$B30) -> 264600 | AQ30: 9 | AS30: =AQ30+AR30 -> 9 | AT30: =+AS30-AV30 -> 9 | AU30: =((AS30-AT30)*$B30) -> 0 | AX30: =+AV30+AW30 -> 0 | AY30: =+AX30-BA30 -> 0 | AZ30: =((AX30-AY30)*$B30) -> 0 | BC30: =+BA30+BB30 -> 0 | BD30: =+BC30-BF30 -> 0 | BE30: =((BC30-BD30)*$B30) -> 0 | BH30: =+BF30+BG30 -> 0 | BI30: =+BH30-BK30 -> 0 | BJ30: =((BH30-BI30)*$B30) -> 0
A31: JALEA FACIAL | B31: 35000 | F31: =+E31-H31 -> 0 | G31: =((E31-F31)*$B31) -> 0 | K31: =+J31-M31 -> 0 | L31: =((J31-K31)*$B31) -> 0 | P31: =+O31-R31 -> 0 | Q31: =((O31-P31)*$B31) -> 0 | U31: =+T31-W31 -> 0 | V31: =((T31-U31)*$B31) -> 0 | Y31: =+W31+X31 -> 0 | Z31: =+Y31-AB31 -> 0 | AA31: =((Y31-Z31)*$B31) -> 0 | AD31: =+AB31+AC31 -> 0 | AE31: =+AD31-AG31 -> 0 | AF31: =((AD31-AE31)*$B31) -> 0 | AG31: 0 | AI31: =+AG31+AH31 -> 0 | AJ31: =+AI31-AL31 -> 0 | AK31: =((AI31-AJ31)*$B31) -> 0 | AL31: 0 | AN31: =+AL31+AM31 -> 0 | AO31: =+AN31-AQ31 -> 0 | AP31: =((AN31-AO31)*$B31) -> 0 | AQ31: 0 | AS31: =AQ31+AR31 -> 0 | AT31: =+AS31-AV31 -> 0 | AU31: =((AS31-AT31)*$B31) -> 0 | AX31: =+AV31+AW31 -> 0 | AY31: =+AX31-BA31 -> 0 | AZ31: =((AX31-AY31)*$B31) -> 0 | BC31: =+BA31+BB31 -> 0 | BD31: =+BC31-BF31 -> 0 | BE31: =((BC31-BD31)*$B31) -> 0 | BH31: =+BF31+BG31 -> 0 | BI31: =+BH31-BK31 -> 0 | BJ31: =((BH31-BI31)*$B31) -> 0
A32: MASCARA REPARADORA GORRO | B32: 42000 | F32: =+E32-H32 -> 0 | G32: =((E32-F32)*$B32) -> 0 | K32: =+J32-M32 -> 0 | L32: =((J32-K32)*$B32) -> 0 | P32: =+O32-R32 -> 0 | Q32: =((O32-P32)*$B32) -> 0 | U32: =+T32-W32 -> 0 | V32: =((T32-U32)*$B32) -> 0 | Y32: =+W32+X32 -> 0 | Z32: =+Y32-AB32 -> 0 | AA32: =((Y32-Z32)*$B32) -> 0 | AD32: =+AB32+AC32 -> 0 | AE32: =+AD32-AG32 -> 0 | AF32: =((AD32-AE32)*$B32) -> 0 | AG32: 0 | AI32: =+AG32+AH32 -> 0 | AJ32: =+AI32-AL32 -> 0 | AK32: =((AI32-AJ32)*$B32) -> 0 | AL32: 0 | AM32: 2 | AN32: =+AL32+AM32 -> 2 | AO32: =+AN32-AQ32 -> 2 | AP32: =((AN32-AO32)*$B32) -> 0 | AQ32: 0 | AS32: =AQ32+AR32 -> 0 | AT32: =+AS32-AV32 -> 0 | AU32: =((AS32-AT32)*$B32) -> 0 | AX32: =+AV32+AW32 -> 0 | AY32: =+AX32-BA32 -> 0 | AZ32: =((AX32-AY32)*$B32) -> 0 | BC32: =+BA32+BB32 -> 0 | BD32: =+BC32-BF32 -> 0 | BE32: =((BC32-BD32)*$B32) -> 0 | BH32: =+BF32+BG32 -> 0 | BI32: =+BH32-BK32 -> 0 | BJ32: =((BH32-BI32)*$B32) -> 0
A33: TRATAMIENTO MACA | B33: 52500 | F33: =+E33-H33 -> 0 | G33: =((E33-F33)*$B33) -> 0 | K33: =+J33-M33 -> 0 | L33: =((J33-K33)*$B33) -> 0 | P33: =+O33-R33 -> 0 | Q33: =((O33-P33)*$B33) -> 0 | U33: =+T33-W33 -> 0 | V33: =((T33-U33)*$B33) -> 0 | Y33: =+W33+X33 -> 0 | Z33: =+Y33-AB33 -> 0 | AA33: =((Y33-Z33)*$B33) -> 0 | AD33: =+AB33+AC33 -> 0 | AE33: =+AD33-AG33 -> 0 | AF33: =((AD33-AE33)*$B33) -> 0 | AG33: 0 | AI33: =+AG33+AH33 -> 0 | AJ33: =+AI33-AL33 -> 0 | AK33: =((AI33-AJ33)*$B33) -> 0 | AL33: 0 | AM33: 6 | AN33: =+AL33+AM33 -> 6 | AO33: =+AN33-AQ33 -> 3 | AP33: =((AN33-AO33)*$B33) -> 157500 | AQ33: 3 | AS33: =AQ33+AR33 -> 3 | AT33: =+AS33-AV33 -> 3 | AU33: =((AS33-AT33)*$B33) -> 0 | AX33: =+AV33+AW33 -> 0 | AY33: =+AX33-BA33 -> 0 | AZ33: =((AX33-AY33)*$B33) -> 0 | BC33: =+BA33+BB33 -> 0 | BD33: =+BC33-BF33 -> 0 | BE33: =((BC33-BD33)*$B33) -> 0 | BH33: =+BF33+BG33 -> 0 | BI33: =+BH33-BK33 -> 0 | BJ33: =((BH33-BI33)*$B33) -> 0
F34: =+E34-H34 -> 0 | G34: =((E34-F34)*$B34) -> 0 | K34: =+J34-M34 -> 0 | L34: =((J34-K34)*$B34) -> 0 | P34: =+O34-R34 -> 0 | Q34: =((O34-P34)*$B34) -> 0 | U34: =+T34-W34 -> 0 | V34: =((T34-U34)*$B34) -> 0 | Y34: =+W34+X34 -> 0 | Z34: =+Y34-AB34 -> 0 | AA34: =((Y34-Z34)*$B34) -> 0 | AD34: =+AB34+AC34 -> 0 | AE34: =+AD34-AG34 -> 0 | AF34: =((AD34-AE34)*$B34) -> 0 | AI34: =+AG34+AH34 -> 0 | AJ34: =+AI34-AL34 -> 0 | AK34: =((AI34-AJ34)*$B34) -> 0 | AN34: =+AL34+AM34 -> 0 | AO34: =+AN34-AQ34 -> 0 | AP34: =((AN34-AO34)*$B34) -> 0 | AS34: =AQ34+AR34 -> 0 | AT34: =+AS34-AV34 -> 0 | AU34: =((AS34-AT34)*$B34) -> 0 | AX34: =+AV34+AW34 -> 0 | AY34: =+AX34-BA34 -> 0 | AZ34: =((AX34-AY34)*$B34) -> 0 | BC34: =+BA34+BB34 -> 0 | BD34: =+BC34-BF34 -> 0 | BE34: =((BC34-BD34)*$B34) -> 0 | BH34: =+BF34+BG34 -> 0 | BI34: =+BH34-BK34 -> 0 | BJ34: =((BH34-BI34)*$B34) -> 0
F35: =+E35-H35 -> 0 | G35: =((E35-F35)*$B35) -> 0 | K35: =+J35-M35 -> 0 | L35: =((J35-K35)*$B35) -> 0 | P35: =+O35-R35 -> 0 | Q35: =((O35-P35)*$B35) -> 0 | U35: =+T35-W35 -> 0 | V35: =((T35-U35)*$B35) -> 0 | Y35: =+W35+X35 -> 0 | Z35: =+Y35-AB35 -> 0 | AA35: =((Y35-Z35)*$B35) -> 0 | AD35: =+AB35+AC35 -> 0 | AE35: =+AD35-AG35 -> 0 | AF35: =((AD35-AE35)*$B35) -> 0 | AI35: =+AG35+AH35 -> 0 | AJ35: =+AI35-AL35 -> 0 | AK35: =((AI35-AJ35)*$B35) -> 0 | AN35: =+AL35+AM35 -> 0 | AO35: =+AN35-AQ35 -> 0 | AP35: =((AN35-AO35)*$B35) -> 0 | AS35: =AQ35+AR35 -> 0 | AT35: =+AS35-AV35 -> 0 | AU35: =((AS35-AT35)*$B35) -> 0 | AX35: =+AV35+AW35 -> 0 | AY35: =+AX35-BA35 -> 0 | AZ35: =((AX35-AY35)*$B35) -> 0 | BC35: =+BA35+BB35 -> 0 | BD35: =+BC35-BF35 -> 0 | BE35: =((BC35-BD35)*$B35) -> 0 | BH35: =+BF35+BG35 -> 0 | BI35: =+BH35-BK35 -> 0 | BJ35: =((BH35-BI35)*$B35) -> 0
F36: =+E36-H36 -> 0 | G36: =((E36-F36)*$B36) -> 0 | K36: =+J36-M36 -> 0 | L36: =((J36-K36)*$B36) -> 0 | P36: =+O36-R36 -> 0 | Q36: =((O36-P36)*$B36) -> 0 | U36: =+T36-W36 -> 0 | V36: =((T36-U36)*$B36) -> 0 | Y36: =+W36+X36 -> 0 | Z36: =+Y36-AB36 -> 0 | AA36: =((Y36-Z36)*$B36) -> 0 | AD36: =+AB36+AC36 -> 0 | AE36: =+AD36-AG36 -> 0 | AF36: =((AD36-AE36)*$B36) -> 0 | AI36: =+AG36+AH36 -> 0 | AJ36: =+AI36-AL36 -> 0 | AK36: =((AI36-AJ36)*$B36) -> 0 | AN36: =+AL36+AM36 -> 0 | AO36: =+AN36-AQ36 -> 0 | AP36: =((AN36-AO36)*$B36) -> 0 | AS36: =AQ36+AR36 -> 0 | AT36: =+AS36-AV36 -> 0 | AU36: =((AS36-AT36)*$B36) -> 0 | AX36: =+AV36+AW36 -> 0 | AY36: =+AX36-BA36 -> 0 | AZ36: =((AX36-AY36)*$B36) -> 0 | BC36: =+BA36+BB36 -> 0 | BD36: =+BC36-BF36 -> 0 | BE36: =((BC36-BD36)*$B36) -> 0 | BH36: =+BF36+BG36 -> 0 | BI36: =+BH36-BK36 -> 0 | BJ36: =((BH36-BI36)*$B36) -> 0
F37: =+E37-H37 -> 0 | G37: =((E37-F37)*$B37) -> 0 | K37: =+J37-M37 -> 0 | L37: =((J37-K37)*$B37) -> 0 | P37: =+O37-R37 -> 0 | Q37: =((O37-P37)*$B37) -> 0 | U37: =+T37-W37 -> 0 | V37: =((T37-U37)*$B37) -> 0 | Y37: =+W37+X37 -> 0 | Z37: =+Y37-AB37 -> 0 | AA37: =((Y37-Z37)*$B37) -> 0 | AD37: =+AB37+AC37 -> 0 | AE37: =+AD37-AG37 -> 0 | AF37: =((AD37-AE37)*$B37) -> 0 | AI37: =+AG37+AH37 -> 0 | AJ37: =+AI37-AL37 -> 0 | AK37: =((AI37-AJ37)*$B37) -> 0 | AN37: =+AL37+AM37 -> 0 | AO37: =+AN37-AQ37 -> 0 | AP37: =((AN37-AO37)*$B37) -> 0 | AS37: =AQ37+AR37 -> 0 | AT37: =+AS37-AV37 -> 0 | AU37: =((AS37-AT37)*$B37) -> 0 | AX37: =+AV37+AW37 -> 0 | AY37: =+AX37-BA37 -> 0 | AZ37: =((AX37-AY37)*$B37) -> 0 | BC37: =+BA37+BB37 -> 0 | BD37: =+BC37-BF37 -> 0 | BE37: =((BC37-BD37)*$B37) -> 0 | BH37: =+BF37+BG37 -> 0 | BI37: =+BH37-BK37 -> 0 | BJ37: =((BH37-BI37)*$B37) -> 0
G38: =+SUM(G3:G37) -> 0 | L38: =+SUM(L3:L37) -> 0 | Q38: =UPLUS(SUM(Q3:Q37)) -> #NAME? | V38: =+SUM(V3:V37) -> 0 | AA38: =SUM(AA3:AA37) -> 0 | AF38: =+SUM(AF3:AF32) -> 4076800 | AK38: =+SUM(AK3:AK32) -> 3759000 | AP38: =+SUM(AP3:AP37) -> 3738000 | AU38: =+SUM(AU3:AU37) -> 0 | AZ38: =+SUM(AZ3:AZ37) -> 0 | BE38: =+SUM(BE3:BE37) -> 0 | BJ38: =+SUM(BJ3:BJ37) -> 0

Sheet MZ
A1: MARIANA ZAPATA | C1: ENERO | H1: FEBRERO | M1: MARZO | R1: ABRIL | W1: MAYO | AB1: JUNIO | AG1: JULIO | AL1: AGOSTO | AQ1: SEPTIEMBRE | AV1: OCTUBRE | BA1: NOVIEMBRE | BF1: DICIEMBRE | BK1: ENERO
A2: PRODUCTO | B2: VR. COMPRA | C2: INV.I | D2: Entra | E2: Saldo | F2: SALIDA | G2: TOTAL | H2: INV.I | I2: Entra | J2: Saldo | K2: SALIDA | L2: TOTAL | M2: INV.I | N2: Entra | O2: Saldo | P2: SALIDA | Q2: TOTAL | R2: INV.I | S2: Entra | T2: Saldo | U2: SALIDA | V2: TOTAL | W2: INV.I | X2: Entra | Y2: Saldo | Z2: SALIDA | AA2: TOTAL | AB2: INV.I | AC2: Entra | AD2: Saldo | AE2: SALIDA | AF2: TOTAL | AG2: INV.I | AH2: Entra | AI2: Saldo | AJ2: SALIDA | AK2: TOTAL | AL2: INV.I | AM2: Entra | AN2: Saldo | AO2: SALIDA | AP2: TOTAL | AQ2: INV.I | AR2: Entra | AS2: Saldo | AT2: SALIDA | AU2: TOTAL | AV2: INV.I | AW2: Entra | AX2: Saldo | AY2: SALIDA | AZ2: TOTAL | BA2: INV.I | BB2: Entra | BC2: Saldo | BD2: SALIDA | BE2: TOTAL | BF2: INV.I | BG2: Entra | BH2: Saldo | BI2: SALIDA | BJ2: TOTAL | BK2: INV.I
A3: SHAMPOO | B3: 31000 | F3: =+E3-H3 -> 0 | G3: =((E3-F3)*$B3) -> 0 | K3: =+J3-M3 -> 0 | L3: =((J3-K3)*$B3) -> 0 | P3: =+O3-R3 -> 0 | Q3: =((O3-P3)*$B3) -> 0 | U3: =+T3-W3 -> 0 | V3: =((T3-U3)*$B3) -> 0 | Z3: =+Y3-AB3 -> 0 | AA3: =((Y3-Z3)*$B3) -> 0 | AE3: =+AD3-AG3 -> -44 | AF3: =((AD3-AE3)*$B3) -> 1364000 | AG3: 44 | AI3: =+AG3+AH3 -> 44 | AJ3: =+AI3-AL3 -> 2 | AK3: =((AI3-AJ3)*$B3) -> 1302000 | AL3: 42 | AN3: =+AL3+AM3 -> 42 | AO3: =+AN3-AQ3 -> 0 | AP3: =((AN3-AO3)*$B3) -> 1302000 | AQ3: 42 | AS3: =+AQ3+AR3 -> 42 | AT3: =+AS3-AV3 -> 42 | AU3: =((AS3-AT3)*$B3) -> 0 | AX3: =+AV3+AW3 -> 0 | AY3: =+AX3-BA3 -> 0 | AZ3: =((AX3-AY3)*$B3) -> 0 | BC3: =+BA3+BB3 -> 0 | BD3: =+BC3-BF3 -> 0 | BE3: =((BC3-BD3)*$B3) -> 0 | BH3: =+BF3+BG3 -> 0 | BI3: =+BH3-BK3 -> 0 | BJ3: =((BH3-BI3)*$B3) -> 0
A4: ACONDICIONADOR | B4: 30000 | F4: =+E4-H4 -> 0 | G4: =((E4-F4)*$B4) -> 0 | K4: =+J4-M4 -> 0 | L4: =((J4-K4)*$B4) -> 0 | P4: =+O4-R4 -> 0 | Q4: =((O4-P4)*$B4) -> 0 | U4: =+T4-W4 -> 0 | V4: =((T4-U4)*$B4) -> 0 | Z4: =+Y4-AB4 -> 0 | AA4: =((Y4-Z4)*$B4) -> 0 | AE4: =+AD4-AG4 -> -30 | AF4: =((AD4-AE4)*$B4) -> 900000 | AG4: 30 | AI4: =+AG4+AH4 -> 30 | AJ4: =+AI4-AL4 -> 2 | AK4: =((AI4-AJ4)*$B4) -> 840000 | AL4: 28 | AN4: =+AL4+AM4 -> 28 | AO4: =+AN4-AQ4 -> 0 | AP4: =((AN4-AO4)*$B4) -> 840000 | AQ4: 28 | AS4: =+AQ4+AR4 -> 28 | AT4: =+AS4-AV4 -> 28 | AU4: =((AS4-AT4)*$B4) -> 0 | AX4: =+AV4+AW4 -> 0 | AY4: =+AX4-BA4 -> 0 | AZ4: =((AX4-AY4)*$B4) -> 0 | BC4: =+BA4+BB4 -> 0 | BD4: =+BC4-BF4 -> 0 | BE4: =((BC4-BD4)*$B4) -> 0 | BH4: =+BF4+BG4 -> 0 | BI4: =+BH4-BK4 -> 0 | BJ4: =((BH4-BI4)*$B4) -> 0
A5: PERFUME CAPILAR MZ | B5: 22000 | AE5: =+AD5-AG5 -> -4 | AF5: =((AD5-AE5)*$B5) -> 88000 | AG5: 4 | AI5: =+AG5+AH5 -> 4 | AJ5: =+AI5-AL5 -> 0 | AK5: =((AI5-AJ5)*$B5) -> 88000 | AL5: 4 | AN5: =+AL5+AM5 -> 4 | AO5: =+AN5-AQ5 -> 0 | AP5: =((AN5-AO5)*$B5) -> 88000 | AQ5: 4
A6: MASCARILLA CAPILAR FRUTAS MZ | B6: 37000 | F6: =+E6-H6 -> 0 | G6: =((E6-F6)*$B6) -> 0 | K6: =+J6-M6 -> 0 | L6: =((J6-K6)*$B6) -> 0 | P6: =+O6-R6 -> 0 | Q6: =((O6-P6)*$B6) -> 0 | U6: =+T6-W6 -> 0 | V6: =((T6-U6)*$B6) -> 0 | Z6: =+Y6-AB6 -> 0 | AA6: =((Y6-Z6)*$B6) -> 0 | AE6: =+AD6-AG6 -> 0 | AF6: =((AD6-AE6)*$B6) -> 0 | AI6: =+AG6+AH6 -> 0 | AJ6: =+AI6-AL6 -> -4 | AK6: =((AI6-AJ6)*$B6) -> 148000 | AL6: 4 | AN6: =+AL6+AM6 -> 4 | AO6: =+AN6-AQ6 -> 4 | AP6: =((AN6-AO6)*$B6) -> 0 | AQ6: 0 | AS6: =+AQ6+AR6 -> 0 | AT6: =+AS6-AV6 -> 0 | AU6: =((AS6-AT6)*$B6) -> 0 | AX6: =+AV6+AW6 -> 0 | AY6: =+AX6-BA6 -> 0 | AZ6: =((AX6-AY6)*$B6) -> 0 | BB6: 3 | BC6: =+BA6+BB6 -> 3 | BD6: =+BC6-BF6 -> 3 | BE6: =((BC6-BD6)*$B6) -> 0 | BH6: =+BF6+BG6 -> 0 | BI6: =+BH6-BK6 -> 0 | BJ6: =((BH6-BI6)*$B6) -> 0
G7: =+SUM(G3:G6) -> 0 | L7: =+SUM(L3:L6) -> 0 | Q7: =+SUM(Q3:Q6) -> 0 | V7: =+SUM(V3:V6) -> 0 | AA7: =+SUM(AA3:AA6) -> 0 | AF7: =+SUM(AF3:AF6) -> 2352000 | AK7: =+SUM(AK3:AK6) -> 2378000 | AP7: =+SUM(AP3:AP6) -> 2230000 | AU7: =+SUM(AU3:AU6) -> 0 | AZ7: =+SUM(AZ3:AZ6) -> 0 | BE7: =+SUM(BE3:BE6) -> 0 | BJ7: =+SUM(BJ3:BJ6) -> 0

Sheet CEPILLOS
A1: CEPILLOS | C1: ENERO | H1: FEBRERO | M1: MARZO | R1: ABRIL | W1: MAYO | AB1: JUNIO | AG1: JULIO | AL1: AGOSTO | AQ1: SEPTIEMBRE | AV1: OCTUBRE | BA1: NOVIEMBRE | BF1: DICIEMBRE | BK1: ENERO
A2: PRODUCTO | B2: VR. COMPRA | C2: INV.I | D2: Entra | E2: Saldo | F2: SALIDA | G2: TOTAL | H2: INV.I | I2: Entra | J2: Saldo | K2: SALIDA | L2: TOTAL | M2: INV.I | N2: Entra | O2: Saldo | P2: SALIDA | Q2: TOTAL | R2: INV.I | S2: Entra | T2: Saldo | U2: SALIDA | V2: TOTAL | W2: INV.I | X2: Entra | Y2: Saldo | Z2: SALIDA | AA2: TOTAL | AB2: INV.I | AC2: Entra | AD2: Saldo | AE2: SALIDA | AF2: TOTAL | AG2: INV.I | AH2: Entra | AI2: Saldo | AJ2: SALIDA | AK2: TOTAL | AL2: INV.I | AM2: Entra | AN2: Saldo | AO2: SALIDA | AP2: TOTAL | AQ2: INV.I | AR2: Entra | AS2: Saldo | AT2: SALIDA | AU2: TOTAL | AV2: INV.I | AW2: Entra | AX2: Saldo | AY2: SALIDA | AZ2: TOTAL | BA2: INV.I | BB2: Entra | BC2: Saldo | BD2: SALIDA | BE2: TOTAL | BF2: INV.I | BG2: Entra | BH2: Saldo | BI2: SALIDA | BJ2: TOTAL | BK2: INV.I
A3: CEPILLOS MASAJEADOR | B3: 3800 | F3: =+E3-H3 -> 0 | G3: =((E3-F3)*$B3) -> 0 | K3: =+J3-M3 -> 0 | L3: =((J3-K3)*$B3) -> 0 | P3: =+O3-R3 -> 0 | Q3: =((O3-P3)*$B3) -> 0 | U3: =+T3-W3 -> 0 | V3: =((T3-U3)*$B3) -> 0 | Z3: =+Y3-AB3 -> 0 | AA3: =((Y3-Z3)*$B3) -> 0 | AE3: =+AD3-AG3 -> -42 | AF3: =((AD3-AE3)*$B3) -> 159600 | AG3: 42 | AI3: =+AG3+AH3 -> 42 | AJ3: =+AI3-AL3 -> 0 | AK3: =((AI3-AJ3)*$B3) -> 159600 | AL3: 42 | AN3: =+AL3+AM3 -> 42 | AO3: =+AN3-AQ3 -> 2 | AP3: =((AN3-AO3)*$B3) -> 152000 | AQ3: 40 | AS3: =+AQ3+AR3 -> 40 | AT3: =+AS3-AV3 -> 40 | AU3: =((AS3-AT3)*$B3) -> 0 | AX3: =+AV3+AW3 -> 0 | AY3: =+AX3-BA3 -> 0 | AZ3: =((AX3-AY3)*$B3) -> 0 | BC3: =+BA3+BB3 -> 0 | BD3: =+BC3-BF3 -> 0 | BE3: =((BC3-BD3)*$B3) -> 0 | BH3: =+BF3+BG3 -> 0 | BI3: =+BH3-BK3 -> 0 | BJ3: =((BH3-BI3)*$B3) -> 0
A4: CEPILLOS ANTI ENREDOS | B4: 6700 | F4: =+E4-H4 -> 0 | G4: =((E4-F4)*$B4) -> 0 | K4: =+J4-M4 -> 0 | L4: =((J4-K4)*$B4) -> 0 | P4: =+O4-R4 -> 0 | Q4: =((O4-P4)*$B4) -> 0 | U4: =+T4-W4 -> 0 | V4: =((T4-U4)*$B4) -> 0 | Z4: =+Y4-AB4 -> 0 | AA4: =((Y4-Z4)*$B4) -> 0 | AE4: =+AD4-AG4 -> -4 | AF4: =((AD4-AE4)*$B4) -> 26800 | AG4: 4 | AI4: =+AG4+AH4 -> 4 | AJ4: =+AI4-AL4 -> 0 | AK4: =((AI4-AJ4)*$B4) -> 26800 | AL4: 4 | AN4: =+AL4+AM4 -> 4 | AO4: =+AN4-AQ4 -> 0 | AP4: =((AN4-AO4)*$B4) -> 26800 | AQ4: 4 | AS4: =+AQ4+AR4 -> 4 | AT4: =+AS4-AV4 -> 4 | AU4: =((AS4-AT4)*$B4) -> 0 | AX4: =+AV4+AW4 -> 0 | AY4: =+AX4-BA4 -> 0 | AZ4: =((AX4-AY4)*$B4) -> 0 | BC4: =+BA4+BB4 -> 0 | BD4: =+BC4-BF4 -> 0 | BE4: =((BC4-BD4)*$B4) -> 0 | BH4: =+BF4+BG4 -> 0 | BI4: =+BH4-BK4 -> 0 | BJ4: =((BH4-BI4)*$B4) -> 0
A5: CEPILLOS DE BAMBU | B5: 8400 | AE5: =+AD5-AG5 -> 0 | AF5: =((AD5-AE5)*$B5) -> 0 | AG5: 0 | AI5: =+AG5+AH5 -> 0 | AJ5: =+AI5-AL5 -> 0 | AK5: =((AI5-AJ5)*$B5) -> 0 | AL5: 0 | AN5: =+AL5+AM5 -> 0 | AO5: =+AN5-AQ5 -> 0 | AP5: =((AN5-AO5)*$B5) -> 0 | AQ5: 0 | AS5: =+AQ5+AR5 -> 0 | AT5: =+AS5-AV5 -> 0 | AU5: =((AS5-AT5)*$B5) -> 0 | AX5: =+AV5+AW5 -> 0 | AY5: =+AX5-BA5 -> 0
A6: APLICADOR TÓNICO | B6: 2600 | AE6: =+AD6-AG6 -> -2 | AF6: =((AD6-AE6)*$B6) -> 5200 | AG6: 2 | AI6: =+AG6+AH6 -> 2 | AJ6: =+AI6-AL6 -> 0 | AK6: =((AI6-AJ6)*$B6) -> 5200 | AL6: 2 | AN6: =+AL6+AM6 -> 2 | AO6: =+AN6-AQ6 -> 0 | AP6: =((AN6-AO6)*$B6) -> 5200 | AQ6: 2 | AS6: =+AQ6+AR6 -> 2 | AT6: =+AS6-AV6 -> 2 | AU6: =((AS6-AT6)*$B6) -> 0 | AX6: =+AV6+AW6 -> 0 | AY6: =+AX6-BA6 -> 0
A7: CEPILLO ESQUELETO | B7: 7900 | AE7: =+AD7-AG7 -> -11 | AF7: =((AD7-AE7)*$B7) -> 86900 | AG7: 11 | AI7: =+AG7+AH7 -> 11 | AJ7: =+AI7-AL7 -> 0 | AK7: =((AI7-AJ7)*$B7) -> 86900 | AL7: 11 | AN7: =+AL7+AM7 -> 11 | AO7: =+AN7-AQ7 -> 0 | AP7: =((AN7-AO7)*$B7) -> 86900 | AQ7: 11 | AS7: =+AQ7+AR7 -> 11 | AT7: =+AS7-AV7 -> 11 | AU7: =((AS7-AT7)*$B7) -> 0 | AX7: =+AV7+AW7 -> 0 | AY7: =+AX7-BA7 -> 0
A8: CEPILLO CURLY | B8: 9000 | AE8: =+AD8-AG8 -> -12 | AF8: =((AD8-AE8)*$B8) -> 108000 | AG8: 12 | AI8: =+AG8+AH8 -> 12 | AJ8: =+AI8-AL8 -> 0 | AK8: =((AI8-AJ8)*$B8) -> 108000 | AL8: 12 | AN8: =+AL8+AM8 -> 12 | AO8: =+AN8-AQ8 -> 1 | AP8: =((AN8-AO8)*$B8) -> 99000 | AQ8: 11 | AS8: =+AQ8+AR8 -> 11 | AT8: =+AS8-AV8 -> 11 | AU8: =((AS8-AT8)*$B8) -> 0 | AX8: =+AV8+AW8 -> 0 | AY8: =+AX8-BA8 -> 0
A9: CEPILLO CRESPOS PEQ | B9: 6000 | AE9: =+AD9-AG9 -> -6 | AF9: =((AD9-AE9)*$B9) -> 36000 | AG9: 6 | AI9: =+AG9+AH9 -> 6 | AJ9: =+AI9-AL9 -> 0 | AK9: =((AI9-AJ9)*$B9) -> 36000 | AL9: 6 | AN9: =+AL9+AM9 -> 6 | AO9: =+AN9-AQ9 -> 0 | AP9: =((AN9-AO9)*$B9) -> 36000 | AQ9: 6 | AS9: =+AQ9+AR9 -> 6 | AT9: =+AS9-AV9 -> 6 | AU9: =((AS9-AT9)*$B9) -> 0 | AX9: =+AV9+AW9 -> 0 | AY9: =+AX9-BA9 -> 0
A10: CEPILLO GOTA DESENREDANTE | B10: 6000 | AE10: =+AD10-AG10 -> -12 | AF10: =((AD10-AE10)*$B10) -> 72000 | AG10: 12 | AI10: =+AG10+AH10 -> 12 | AJ10: =+AI10-AL10 -> 0 | AK10: =((AI10-AJ10)*$B10) -> 72000 | AL10: 12 | AN10: =+AL10+AM10 -> 12 | AO10: =+AN10-AQ10 -> 1 | AP10: =((AN10-AO10)*$B10) -> 66000 | AQ10: 11 | AS10: =+AQ10+AR10 -> 11 | AT10: =+AS10-AV10 -> 11 | AU10: =((AS10-AT10)*$B10) -> 0 | AX10: =+AV10+AW10 -> 0 | AY10: =+AX10-BA10 -> 0
A11: CEPILLO LABEATY PROFESIONAL | B11: 44000 | AM11: 6 | AN11: =+AL11+AM11 -> 6 | AO11: =+AN11-AQ11 -> 4 | AP11: =((AN11-AO11)*$B11) -> 88000 | AQ11: 2 | AS11: =+AQ11+AR11 -> 2 | AT11: =+AS11-AV11 -> 2 | AU11: =((AS11-AT11)*$B11) -> 0
A12: CEPILLO PLANCHA | B12: 22950 | AE12: =+AD12-AG12 -> -4 | AF12: =((AD12-AE12)*$B12) -> 91800 | AG12: 4 | AI12: =+AG12+AH12 -> 4 | AJ12: =+AI12-AL12 -> 0 | AK12: =((AI12-AJ12)*$B12) -> 91800 | AL12: 4 | AN12: =+AL12+AM12 -> 4 | AO12: =+AN12-AQ12 -> 0 | AP12: =((AN12-AO12)*$B12) -> 91800 | AQ12: 4 | AS12: =+AQ12+AR12 -> 4 | AT12: =+AS12-AV12 -> 4 | AU12: =((AS12-AT12)*$B12) -> 0 | AX12: =+AV12+AW12 -> 0 | AY12: =+AX12-BA12 -> 0
G13: =+SUM(G3:G12) -> 0 | L13: =+SUM(L3:L12) -> 0 | Q13: =+SUM(Q3:Q12) -> 0 | V13: =+SUM(V3:V12) -> 0 | AA13: =+SUM(AA3:AA12) -> 0 | AF13: =+SUM(AF3:AF12) -> 586300 | AK13: =+SUM(AK3:AK12) -> 586300 | AP13: =+SUM(AP3:AP12) -> 651700 | AU13: =+SUM(AU3:AU12) -> 0 | AZ13: =+SUM(AZ3:AZ12) -> 0 | BE13: =+SUM(BE3:BE12) -> 0 | BJ13: =+SUM(BJ3:BJ12) -> 0

Sheet LB
A1: TRATAMIENTOS LB | C1: ENERO | H1: FEBRERO | M1: MARZO | R1: ABRIL | W1: MAYO | AB1: JUNIO | AG1: JULIO | AL1: AGOSTO | AQ1: SEPTIEMBRE | AV1: OCTUBRE | BA1: NOVIEMBRE | BF1: DICIEMBRE | BK1: ENERO
A2: PRODUCTO | B2: VR. COMPRA | C2: INV.I | D2: Entra | E2: Saldo | F2: SALIDA | G2: TOTAL | H2: INV.I | I2: Entra | J2: Saldo | K2: SALIDA | L2: TOTAL | M2: INV.I | N2: Entra | O2: Saldo | P2: SALIDA | Q2: TOTAL | R2: INV.I | S2: Entra | T2: Saldo | U2: SALIDA | V2: TOTAL | W2: INV.I | X2: Entra | Y2: Saldo | Z2: SALIDA | AA2: TOTAL | AB2: INV.I | AC2: Entra | AD2: Saldo | AE2: SALIDA | AF2: TOTAL | AG2: INV.I | AH2: Entra | AI2: Saldo | AJ2: SALIDA | AK2: TOTAL | AL2: INV.I | AM2: Entra | AN2: Saldo | AO2: SALIDA | AP2: TOTAL | AQ2: INV.I | AR2: Entra | AS2: Saldo | AT2: SALIDA | AU2: TOTAL | AV2: INV.I | AW2: Entra | AX2: Saldo | AY2: SALIDA | AZ2: TOTAL | BA2: INV.I | BB2: Entra | BC2: Saldo | BD2: SALIDA | BE2: TOTAL | BF2: INV.I | BG2: Entra | BH2: Saldo | BI2: SALIDA | BJ2: TOTAL | BK2: INV.I
A3: TÓNICO FACIAL | B3: 21000 | F3: =+E3-H3 -> 0 | G3: =((E3-F3)*$B3) -> 0 | K3: =+J3-M3 -> 0 | L3: =((J3-K3)*$B3) -> 0 | P3: =+O3-R3 -> 0 | Q3: =((O3-P3)*$B3) -> 0 | U3: =+T3-W3 -> 0 | V3: =((T3-U3)*$B3) -> 0 | Z3: =+Y3-AB3 -> 0 | AA3: =((Y3-Z3)*$B3) -> 0 | AE3: =+AD3-AG3 -> -18 | AF3: =((AD3-AE3)*$B3) -> 378000 | AG3: 18 | AI3: =+AG3+AH3 -> 18 | AJ3: =+AI3-AL3 -> 1 | AK3: =((AI3-AJ3)*$B3) -> 357000 | AL3: 17 | AN3: =+AL3+AM3 -> 17 | AO3: =+AN3-AQ3 -> 7 | AP3: =((AN3-AO3)*$B3) -> 210000 | AQ3: 10 | AS3: =+AQ3+AR3 -> 10 | AT3: =+AS3-AV3 -> 10 | AU3: =((AS3-AT3)*$B3) -> 0 | AX3: =+AV3+AW3 -> 0 | AY3: =+AX3-BA3 -> 0 | AZ3: =((AX3-AY3)*$B3) -> 0 | BC3: =+BA3+BB3 -> 0 | BD3: =+BC3-BF3 -> 0 | BE3: =((BC3-BD3)*$B3) -> 0 | BH3: =+BF3+BG3 -> 0 | BI3: =+BH3-BK3 -> 0 | BJ3: =((BH3-BI3)*$B3) -> 0
A4: GEL INTIMO | B4: 28000 | F4: =+E4-H4 -> 0 | G4: =((E4-F4)*$B4) -> 0 | K4: =+J4-M4 -> 0 | L4: =((J4-K4)*$B4) -> 0 | P4: =+O4-R4 -> 0 | Q4: =((O4-P4)*$B4) -> 0 | U4: =+T4-W4 -> 0 | V4: =((T4-U4)*$B4) -> 0 | Z4: =+Y4-AB4 -> 0 | AA4: =((Y4-Z4)*$B4) -> 0 | AE4: =+AD4-AG4 -> -16 | AF4: =((AD4-AE4)*$B4) -> 448000 | AG4: 16 | AI4: =+AG4+AH4 -> 16 | AJ4: =+AI4-AL4 -> 0 | AK4: =((AI4-AJ4)*$B4) -> 448000 | AL4: 16 | AN4: =+AL4+AM4 -> 16 | AO4: =+AN4-AQ4 -> 1 | AP4: =((AN4-AO4)*$B4) -> 420000 | AQ4: 15 | AS4: =+AQ4+AR4 -> 15 | AT4: =+AS4-AV4 -> 15 | AU4: =((AS4-AT4)*$B4) -> 0 | AX4: =+AV4+AW4 -> 0 | AY4: =+AX4-BA4 -> 0 | AZ4: =((AX4-AY4)*$B4) -> 0 | BC4: =+BA4+BB4 -> 0 | BD4: =+BC4-BF4 -> 0 | BE4: =((BC4-BD4)*$B4) -> 0 | BH4: =+BF4+BG4 -> 0 | BI4: =+BH4-BK4 -> 0 | BJ4: =((BH4-BI4)*$B4) -> 0
A5: ÁCIDO HIALURÓNICO | B5: 24000 | AE5: =+AD5-AG5 -> -8 | AF5: =((AD5-AE5)*$B5) -> 192000 | AG5: 8 | AI5: =+AG5+AH5 -> 8 | AJ5: =+AI5-AL5 -> 1 | AK5: =((AI5-AJ5)*$B5) -> 168000 | AL5: 7 | AN5: =+AL5+AM5 -> 7 | AO5: =+AN5-AQ5 -> 0 | AP5: =((AN5-AO5)*$B5) -> 168000 | AQ5: 7 | AS5: =+AQ5+AR5 -> 7 | AT5: =+AS5-AV5 -> 7 | AU5: =((AS5-AT5)*$B5) -> 0
A6: PANTALLA SOLAR | B6: 19000 | AE6: =+AD6-AG6 -> -1 | AF6: =((AD6-AE6)*$B6) -> 19000 | AG6: 1 | AI6: =+AG6+AH6 -> 1 | AJ6: =+AI6-AL6 -> 0 | AK6: =((AI6-AJ6)*$B6) -> 19000 | AL6: 1 | AN6: =+AL6+AM6 -> 1 | AO6: =+AN6-AQ6 -> 0 | AP6: =((AN6-AO6)*$B6) -> 19000 | AQ6: 1 | AS6: =+AQ6+AR6 -> 1 | AT6: =+AS6-AV6 -> 1 | AU6: =((AS6-AT6)*$B6) -> 0
A7: DESODORANTE ACLARANTE | B7: 21000 | AE7: =+AD7-AG7 -> -4 | AF7: =((AD7-AE7)*$B7) -> 84000 | AG7: 4 | AI7: =+AG7+AH7 -> 4 | AJ7: =+AI7-AL7 -> 0 | AK7: =((AI7-AJ7)*$B7) -> 84000 | AL7: 4 | AN7: =+AL7+AM7 -> 4 | AO7: =+AN7-AQ7 -> 0 | AP7: =((AN7-AO7)*$B7) -> 84000 | AQ7: 4 | AS7: =+AQ7+AR7 -> 4 | AT7: =+AS7-AV7 -> 4 | AU7: =((AS7-AT7)*$B7) -> 0
G8: =+SUM(G3:G7) -> 0 | L8: =+SUM(L3:L7) -> 0 | Q8: =+SUM(Q3:Q7) -> 0 | V8: =+SUM(V3:V7) -> 0 | AA8: =+SUM(AA3:AA7) -> 0 | AF8: =+SUM(AF3:AF7) -> 1121000 | AK8: =+SUM(AK3:AK7) -> 1076000 | AP8: =+SUM(AP3:AP7) -> 901000 | AU8: =+SUM(AU3:AU7) -> 0 | AZ8: =+SUM(AZ3:AZ7) -> 0 | BE8: =+SUM(BE3:BE7) -> 0 | BJ8: =+SUM(BJ3:BJ7) -> 0

Sheet ML
A1: MILAGROS | C1: ENERO | H1: FEBRERO | M1: MARZO | R1: ABRIL | W1: MAYO | AB1: JUNIO | AG1: JULIO | AL1: AGOSTO | AQ1: SEPTIEMBRE | AV1: OCTUBRE | BA1: NOVIEMBRE | BF1: DICIEMBRE | BK1: ENERO
A2: PRODUCTO | B2: VR. COMPRA | C2: INV.I | D2: Entra | E2: Saldo | F2: SALIDA | G2: TOTAL | H2: INV.I | I2: Entra | J2: Saldo | K2: SALIDA | L2: TOTAL | M2: INV.I | N2: Entra | O2: Saldo | P2: SALIDA | Q2: TOTAL | R2: INV.I | S2: Entra | T2: Saldo | U2: SALIDA | V2: TOTAL | W2: INV.I | X2: Entra | Y2: Saldo | Z2: SALIDA | AA2: TOTAL | AB2: INV.I | AC2: Entra | AD2: Saldo | AE2: SALIDA | AF2: TOTAL | AG2: INV.I | AH2: Entra | AI2: Saldo | AJ2: SALIDA | AK2: TOTAL | AL2: INV.I | AM2: Entra | AN2: Saldo | AO2: SALIDA | AP2: TOTAL | AQ2: INV.I | AR2: Entra | AS2: Saldo | AT2: SALIDA | AU2: TOTAL | AV2: INV.I | AW2: Entra | AX2: Saldo | AY2: SALIDA | AZ2: TOTAL | BA2: INV.I | BB2: Entra | BC2: Saldo | BD2: SALIDA | BE2: TOTAL | BF2: INV.I | BG2: Entra | BH2: Saldo | BI2: SALIDA | BJ2: TOTAL | BK2: INV.I
A3: SH. ARROZ | B3: 20000 | AD3: =+AB3+AC3 -> 0 | AE3: =+AD3-AG3 -> -18 | AF3: =((AD3-AE3)*$B3) -> 360000 | AG3: 18 | AI3: =+AG3+AH3 -> 18 | AJ3: =+AI3-AL3 -> 1 | AK3: =((AI3-AJ3)*$B3) -> 340000 | AL3: 17 | AN3: =+AL3+AM3 -> 17 | AO3: =+AN3-AQ3 -> 2 | AP3: =((AN3-AO3)*$B3) -> 300000 | AQ3: 15 | AS3: =+AQ3+AR3 -> 15 | AT3: =+AS3-AV3 -> 15 | AU3: =((AS3-AT3)*$B3) -> 0 | AX3: =+AV3+AW3 -> 0 | AY3: =+AX3-BA3 -> 0 | AZ3: =((AX3-AY3)*$B3) -> 0 | BC3: =+BA3+BB3 -> 0 | BD3: =+BC3-BF3 -> 0 | BE3: =((BC3-BD3)*$B3) -> 0 | BH3: =+BF3+BG3 -> 0 | BI3: =+BH3-BK3 -> 0 | BJ3: =((BH3-BI3)*$B3) -> 0
A4: AC. ARROZ | B4: 21000 | AD4: =+AB4+AC4 -> 0 | AE4: =+AD4-AG4 -> -18 | AF4: =((AD4-AE4)*$B4) -> 378000 | AG4: 18 | AI4: =+AG4+AH4 -> 18 | AJ4: =+AI4-AL4 -> 1 | AK4: =((AI4-AJ4)*$B4) -> 357000 | AL4: 17 | AN4: =+AL4+AM4 -> 17 | AO4: =+AN4-AQ4 -> 2 | AP4: =((AN4-AO4)*$B4) -> 315000 | AQ4: 15 | AS4: =+AQ4+AR4 -> 15 | AT4: =+AS4-AV4 -> 15 | AU4: =((AS4-AT4)*$B4) -> 0 | AX4: =+AV4+AW4 -> 0 | AY4: =+AX4-BA4 -> 0 | AZ4: =((AX4-AY4)*$B4) -> 0 | BC4: =+BA4+BB4 -> 0 | BD4: =+BC4-BF4 -> 0 | BE4: =((BC4-BD4)*$B4) -> 0 | BH4: =+BF4+BG4 -> 0 | BI4: =+BH4-BK4 -> 0 | BJ4: =((BH4-BI4)*$B4) -> 0
A5: SH. CEBOLLA | B5: 27989 | AD5: =+AB5+AC5 -> 0 | AE5: =+AD5-AG5 -> -35 | AF5: =((AD5-AE5)*$B5) -> 979615 | AG5: 35 | AI5: =+AG5+AH5 -> 35 | AJ5: =+AI5-AL5 -> 4 | AK5: =((AI5-AJ5)*$B5) -> 867659 | AL5: 31 | AN5: =+AL5+AM5 -> 31 | AO5: =+AN5-AQ5 -> 5 | AP5: =((AN5-AO5)*$B5) -> 727714 | AQ5: 26 | AS5: =+AQ5+AR5 -> 26 | AT5: =+AS5-AV5 -> 26 | AU5: =((AS5-AT5)*$B5) -> 0 | AX5: =+AV5+AW5 -> 0 | AY5: =+AX5-BA5 -> 0 | AZ5: =((AX5-AY5)*$B5) -> 0 | BC5: =+BA5+BB5 -> 0 | BD5: =+BC5-BF5 -> 0 | BE5: =((BC5-BD5)*$B5) -> 0 | BH5: =+BF5+BG5 -> 0 | BI5: =+BH5-BK5 -> 0 | BJ5: =((BH5-BI5)*$B5) -> 0
A6: AC.CEBOLLA | B6: 25873 | AD6: =+AB6+AC6 -> 0 | AE6: =+AD6-AG6 -> -17 | AF6: =((AD6-AE6)*$B6) -> 439841 | AG6: 17 | AI6: =+AG6+AH6 -> 17 | AJ6: =+AI6-AL6 -> 5 | AK6: =((AI6-AJ6)*$B6) -> 310476 | AL6: 12 | AN6: =+AL6+AM6 -> 12 | AO6: =+AN6-AQ6 -> 3 | AP6: =((AN6-AO6)*$B6) -> 232857 | AQ6: 9 | AR6: 30 | AS6: =+AQ6+AR6 -> 39 | AT6: =+AS6-AV6 -> 39 | AU6: =((AS6-AT6)*$B6) -> 0 | AX6: =+AV6+AW6 -> 0 | AY6: =+AX6-BA6 -> 0 | AZ6: =((AX6-AY6)*$B6) -> 0 | BC6: =+BA6+BB6 -> 0 | BD6: =+BC6-BF6 -> 0 | BE6: =((BC6-BD6)*$B6) -> 0 | BH6: =+BF6+BG6 -> 0 | BI6: =+BH6-BK6 -> 0 | BJ6: =((BH6-BI6)*$B6) -> 0
A7: SH. HERBAL | B7: 28600 | AD7: =+AB7+AC7 -> 0 | AE7: =+AD7-AG7 -> -10 | AF7: =((AD7-AE7)*$B7) -> 286000 | AG7: 10 | AI7: =+AG7+AH7 -> 10 | AJ7: =+AI7-AL7 -> 0 | AK7: =((AI7-AJ7)*$B9) -> 286000 | AL7: 10 | AN7: =+AL7+AM7 -> 10 | AO7: =+AN7-AQ7 -> 3 | AP7: =((AN7-AO7)*$B7) -> 200200 | AQ7: 7 | AS7: =+AQ7+AR7 -> 7 | AT7: =+AS7-AV7 -> 7 | AU7: =((AS7-AT7)*$B9) -> 0 | AX7: =+AV7+AW7 -> 0 | AY7: =+AX7-BA7 -> 0 | AZ7: =((AX7-AY7)*$B9) -> 0 | BC7: =+BA7+BB7 -> 0 | BD7: =+BC7-BF7 -> 0 | BE7: =((BC7-BD7)*$B9) -> 0 | BH7: =+BF7+BG7 -> 0 | BI7: =+BH7-BK7 -> 0 | BJ7: =((BH7-BI7)*$B9) -> 0
A8: AC. HERBAL | B8: 29000 | AD8: =+AB8+AC8 -> 0 | AE8: =+AD8-AG8 -> -8 | AF8: =((AD8-AE8)*$B8) -> 232000 | AG8: 8 | AI8: =+AG8+AH8 -> 8 | AJ8: =+AI8-AL8 -> 0 | AK8: =((AI8-AJ8)*$B10) -> 232000 | AL8: 8 | AN8: =+AL8+AM8 -> 8 | AO8: =+AN8-AQ8 -> 1 | AP8: =((AN8-AO8)*$B8) -> 203000 | AQ8: 7 | AS8: =+AQ8+AR8 -> 7 | AT8: =+AS8-AV8 -> 7 | AU8: =((AS8-AT8)*$B10) -> 0 | AX8: =+AV8+AW8 -> 0 | AY8: =+AX8-BA8 -> 0 | AZ8: =((AX8-AY8)*$B10) -> 0 | BC8: =+BA8+BB8 -> 0 | BD8: =+BC8-BF8 -> 0 | BE8: =((BC8-BD8)*$B10) -> 0 | BH8: =+BF8+BG8 -> 0 | BI8: =+BH8-BK8 -> 0 | BJ8: =((BH8-BI8)*$B10) -> 0
A9: SH. ULTRANUTRITIVO | B9: 28600 | AD9: =+AB9+AC9 -> 0 | AE9: =+AD9-AG9 -> -9 | AF9: =((AD9-AE9)*$B9) -> 257400 | AG9: 9 | AI9: =+AG9+AH9 -> 9 | AJ9: =+AI9-AL9 -> 0 | AK9: =((AI9-AJ9)*$B11) -> 257400 | AL9: 9 | AN9: =+AL9+AM9 -> 9 | AO9: =+AN9-AQ9 -> 2 | AP9: =((AN9-AO9)*$B9) -> 200200 | AQ9: 7 | AS9: =+AQ9+AR9 -> 7 | AT9: =+AS9-AV9 -> 7 | AU9: =((AS9-AT9)*$B11) -> 0 | AX9: =+AV9+AW9 -> 0 | AY9: =+AX9-BA9 -> 0 | AZ9: =((AX9-AY9)*$B11) -> 0 | BC9: =+BA9+BB9 -> 0 | BD9: =+BC9-BF9 -> 0 | BE9: =((BC9-BD9)*$B11) -> 0 | BH9: =+BF9+BG9 -> 0 | BI9: =+BH9-BK9 -> 0 | BJ9: =((BH9-BI9)*$B11) -> 0
A10: AC. ULTRANUTRITIVO | B10: 29000 | AD10: =+AB10+AC10 -> 0 | AE10: =+AD10-AG10 -> -5 | AF10: =((AD10-AE10)*$B10) -> 145000 | AG10: 5 | AI10: =+AG10+AH10 -> 5 | AJ10: =+AI10-AL10 -> 0 | AK10: =((AI10-AJ10)*$B12) -> 143000 | AL10: 5 | AN10: =+AL10+AM10 -> 5 | AO10: =+AN10-AQ10 -> 3 | AP10: =((AN10-AO10)*$B10) -> 58000 | AQ10: 2 | AR10: 6 | AS10: =+AQ10+AR10 -> 8 | AT10: =+AS10-AV10 -> 8 | AU10: =((AS10-AT10)*$B12) -> 0 | AX10: =+AV10+AW10 -> 0 | AY10: =+AX10-BA10 -> 0 | AZ10: =((AX10-AY10)*$B12) -> 0 | BC10: =+BA10+BB10 -> 0 | BD10: =+BC10-BF10 -> 0 | BE10: =((BC10-BD10)*$B12) -> 0 | BH10: =+BF10+BG10 -> 0 | BI10: =+BH10-BK10 -> 0 | BJ10: =((BH10-BI10)*$B12) -> 0
A11: SH. EMERGENCIA CAPILAR | B11: 28600 | AD11: =+AB11+AC11 -> 0 | AE11: =+AD11-AG11 -> -9 | AF11: =((AD11-AE11)*$B11) -> 257400 | AG11: 9 | AI11: =+AG11+AH11 -> 9 | AJ11: =+AI11-AL11 -> 0 | AK11: =((AI11-AJ11)*$B13) -> 210078 | AL11: 9 | AN11: =+AL11+AM11 -> 9 | AO11: =+AN11-AQ11 -> 0 | AP11: =((AN11-AO11)*$B11) -> 257400 | AQ11: 9 | AS11: =+AQ11+AR11 -> 9 | AT11: =+AS11-AV11 -> 9 | AU11: =((AS11-AT11)*$B13) -> 0 | AX11: =+AV11+AW11 -> 0 | AY11: =+AX11-BA11 -> 0 | AZ11: =((AX11-AY11)*$B13) -> 0 | BC11: =+BA11+BB11 -> 0 | BD11: =+BC11-BF11 -> 0 | BE11: =((BC11-BD11)*$B13) -> 0 | BH11: =+BF11+BG11 -> 0 | BI11: =+BH11-BK11 -> 0 | BJ11: =((BH11-BI11)*$B13) -> 0
A12: SH. MAGÍA CAPILAR | B12: 28600 | AD12: =+AB12+AC12 -> 0 | AE12: =+AD12-AG12 -> -9 | AF12: =((AD12-AE12)*$B12) -> 257400 | AG12: 9 | AI12: =+AG12+AH12 -> 9 | AJ12: =+AI12-AL12 -> 0 | AK12: =((AI12-AJ12)*$B14) -> 257400 | AL12: 9 | AN12: =+AL12+AM12 -> 9 | AO12: =+AN12-AQ12 -> 0 | AP12: =((AN12-AO12)*$B12) -> 257400 | AQ12: 9 | AS12: =+AQ12+AR12 -> 9 | AT12: =+AS12-AV12 -> 9 | AU12: =((AS12-AT12)*$B14) -> 0 | AX12: =+AV12+AW12 -> 0 | AY12: =+AX12-BA12 -> 0 | AZ12: =((AX12-AY12)*$B14) -> 0 | BC12: =+BA12+BB12 -> 0 | BD12: =+BC12-BF12 -> 0 | BE12: =((BC12-BD12)*$B14) -> 0 | BH12: =+BF12+BG12 -> 0 | BI12: =+BH12-BK12 -> 0 | BJ12: =((BH12-BI12)*$B14) -> 0
A13: SH. KIDS | B13: 23342 | AD13: =+AB13+AC13 -> 0 | AE13: =+AD13-AG13 -> -27 | AF13: =((AD13-AE13)*$B13) -> 630234 | AG13: 27 | AI13: =+AG13+AH13 -> 27 | AJ13: =+AI13-AL13 -> 0 | AK13: =((AI13-AJ13)*$B16) -> 729000 | AL13: 27 | AN13: =+AL13+AM13 -> 27 | AO13: =+AN13-AQ13 -> 0 | AP13: =((AN13-AO13)*$B13) -> 630234 | AQ13: 27 | AS13: =+AQ13+AR13 -> 27 | AT13: =+AS13-AV13 -> 27 | AU13: =((AS13-AT13)*$B16) -> 0 | AX13: =+AV13+AW13 -> 0 | AY13: =+AX13-BA13 -> 0 | AZ13: =((AX13-AY13)*$B16) -> 0 | BC13: =+BA13+BB13 -> 0 | BD13: =+BC13-BF13 -> 0 | BE13: =((BC13-BD13)*$B16) -> 0 | BH13: =+BF13+BG13 -> 0 | BI13: =+BH13-BK13 -> 0 | BJ13: =((BH13-BI13)*$B16) -> 0
A14: SH. ANTI CASPA | B14: 28600 | AD14: =+AB14+AC14 -> 0 | AE14: =+AD14-AG14 -> -10 | AF14: =((AD14-AE14)*$B14) -> 286000 | AG14: 10 | AI14: =+AG14+AH14 -> 10 | AJ14: =+AI14-AL14 -> 0 | AK14: =((AI14-AJ14)*$B17) -> 286000 | AL14: 10 | AN14: =+AL14+AM14 -> 10 | AO14: =+AN14-AQ14 -> 1 | AP14: =((AN14-AO14)*$B14) -> 257400 | AQ14: 9 | AS14: =+AQ14+AR14 -> 9 | AT14: =+AS14-AV14 -> 9 | AU14: =((AS14-AT14)*$B17) -> 0 | AX14: =+AV14+AW14 -> 0 | AY14: =+AX14-BA14 -> 0 | AZ14: =((AX14-AY14)*$B17) -> 0 | BC14: =+BA14+BB14 -> 0 | BD14: =+BC14-BF14 -> 0 | BE14: =((BC14-BD14)*$B17) -> 0 | BH14: =+BF14+BG14 -> 0 | BI14: =+BH14-BK14 -> 0 | BJ14: =((BH14-BI14)*$B17) -> 0
A15: SH. EXFOLIANTE PRIME | B15: 23746 | AR15: 30 | AS15: =+AQ15+AR15 -> 30 | AT15: =+AS15-AV15 -> 30 | AU15: =((AS15-AT15)*$B18) -> 0
A16: SH. EXFOLIANTE | B16: 27000 | AD16: =+AB16+AC16 -> 0 | AE16: =+AD16-AG16 -> -8 | AF16: =((AD16-AE16)*$B16) -> 216000 | AG16: 8 | AI16: =+AG16+AH16 -> 8 | AJ16: =+AI16-AL16 -> 0 | AK16: =((AI16-AJ16)*$B19) -> 480000 | AL16: 8 | AN16: =+AL16+AM16 -> 8 | AO16: =+AN16-AQ16 -> 0 | AP16: =((AN16-AO16)*$B16) -> 216000 | AQ16: 8 | AS16: =+AQ16+AR16 -> 8 | AT16: =+AS16-AV16 -> 8 | AU16: =((AS16-AT16)*$B19) -> 0 | AX16: =+AV16+AW16 -> 0 | AY16: =+AX16-BA16 -> 0 | AZ16: =((AX16-AY16)*$B19) -> 0 | BC16: =+BA16+BB16 -> 0 | BD16: =+BC16-BF16 -> 0 | BE16: =((BC16-BD16)*$B19) -> 0 | BH16: =+BF16+BG16 -> 0 | BI16: =+BH16-BK16 -> 0 | BJ16: =((BH16-BI16)*$B19) -> 0
A17: SH. BIO REPOLARIZADOR | B17: 28600 | AD17: =+AB17+AC17 -> 0 | AE17: =+AD17-AG17 -> -6 | AF17: =((AD17-AE17)*$B17) -> 171600 | AG17: 6 | AI17: =+AG17+AH17 -> 6 | AJ17: =+AI17-AL17 -> 0 | AK17: =((AI17-AJ17)*$B20) -> 174000 | AL17: 6 | AN17: =+AL17+AM17 -> 6 | AO17: =+AN17-AQ17 -> 0 | AP17: =((AN17-AO17)*$B17) -> 171600 | AQ17: 6 | AS17: =+AQ17+AR17 -> 6 | AT17: =+AS17-AV17 -> 6 | AU17: =((AS17-AT17)*$B20) -> 0 | AX17: =+AV17+AW17 -> 0 | AY17: =+AX17-BA17 -> 0 | AZ17: =((AX17-AY17)*$B20) -> 0 | BC17: =+BA17+BB17 -> 0 | BD17: =+BC17-BF17 -> 0 | BE17: =((BC17-BD17)*$B20) -> 0 | BH17: =+BF17+BG17 -> 0 | BI17: =+BH17-BK17 -> 0 | BJ17: =((BH17-BI17)*$B20) -> 0
A18: BIO REPOLARIZADOR LITRO | B18: 45000 | AD18: =+AB18+AC18 -> 0 | AE18: =+AD18-AG18 -> -6 | AF18: =((AD18-AE18)*$B18) -> 270000 | AG18: 6 | AI18: =+AG18+AH18 -> 6 | AJ18: =+AI18-AL18 -> 2 | AK18: =((AI18-AJ18)*$B21) -> 116000 | AL18: 4 | AN18: =+AL18+AM18 -> 4 | AO18: =+AN18-AQ18 -> 1 | AP18: =((AN18-AO18)*$B18) -> 135000 | AQ18: 3 | AS18: =+AQ18+AR18 -> 3 | AT18: =+AS18-AV18 -> 3 | AU18: =((AS18-AT18)*$B21) -> 0 | AX18: =+AV18+AW18 -> 0 | AY18: =+AX18-BA18 -> 0 | AZ18: =((AX18-AY18)*$B21) -> 0 | BC18: =+BA18+BB18 -> 0 | BD18: =+BC18-BF18 -> 0 | BE18: =((BC18-BD18)*$B21) -> 0 | BH18: =+BF18+BG18 -> 0 | BI18: =+BH18-BK18 -> 0 | BJ18: =((BH18-BI18)*$B21) -> 0
A19: SH. ARROZ LITRO | B19: 60000 | AD19: =+AB19+AC19 -> 0 | AE19: =+AD19-AG19 -> -1 | AF19: =((AD19-AE19)*$B19) -> 60000 | AG19: 1 | AI19: =+AG19+AH19 -> 1 | AJ19: =+AI19-AL19 -> 0 | AK19: =((AI19-AJ19)*$B22) -> 23577 | AL19: 1 | AN19: =+AL19+AM19 -> 1 | AO19: =+AN19-AQ19 -> 0 | AP19: =((AN19-AO19)*$B19) -> 60000 | AQ19: 1 | AS19: =+AQ19+AR19 -> 1 | AT19: =+AS19-AV19 -> 1 | AU19: =((AS19-AT19)*$B22) -> 0 | AX19: =+AV19+AW19 -> 0 | AY19: =+AX19-BA19 -> 0 | AZ19: =((AX19-AY19)*#REF!) -> #REF! | BC19: =+BA19+BB19 -> 0 | BD19: =+BC19-BF19 -> 0 | BE19: =((BC19-BD19)*#REF!) -> #REF! | BH19: =+BF19+BG19 -> 0 | BI19: =+BH19-BK19 -> 0 | BJ19: =((BH19-BI19)*#REF!) -> #REF!
A20: BIO REPOLARIZADOR PEQ | B20: 29000 | AD20: =+AB20+AC20 -> 0 | AE20: =+AD20-AG20 -> -9 | AF20: =((AD20-AE20)*$B20) -> 261000 | AG20: 9 | AI20: =+AG20+AH20 -> 9 | AJ20: =+AI20-AL20 -> 2 | AK20: =((AI20-AJ20)*$B23) -> 203000 | AL20: 7 | AN20: =+AL20+AM20 -> 7 | AO20: =+AN20-AQ20 -> 2 | AP20: =((AN20-AO20)*$B20) -> 145000 | AQ20: 5 | AR20: 6 | AS20: =+AQ20+AR20 -> 11 | AT20: =+AS20-AV20 -> 11 | AU20: =((AS20-AT20)*$B23) -> 0 | AX20: =+AV20+AW20 -> 0 | AY20: =+AX20-BA20 -> 0 | AZ20: =((AX20-AY20)*#REF!) -> #REF! | BC20: =+BA20+BB20 -> 0 | BD20: =+BC20-BF20 -> 0 | BE20: =((BC20-BD20)*#REF!) -> #REF! | BH20: =+BF20+BG20 -> 0 | BI20: =+BH20-BK20 -> 0 | BJ20: =((BH20-BI20)*#REF!) -> #REF!
A21: TRATAMIENTO RIZOS | B21: 29000 | AD21: =+AB21+AC21 -> 0 | AE21: =+AD21-AG21 -> -10 | AF21: =((AD21-AE21)*$B21) -> 290000 | AG21: 10 | AI21: =+AG21+AH21 -> 10 | AJ21: =+AI21-AL21 -> 4 | AK21: =((AI21-AJ21)*$B24) -> 174000 | AL21: 6 | AN21: =+AL21+AM21 -> 6 | AO21: =+AN21-AQ21 -> -4 | AP21: =((AN21-AO21)*$B21) -> 290000 | AQ21: 10 | AS21: =+AQ21+AR21 -> 10 | AT21: =+AS21-AV21 -> 10 | AU21: =((AS21-AT21)*$B24) -> 0 | AX21: =+AV21+AW21 -> 0 | AY21: =+AX21-BA21 -> 0 | AZ21: =((AX21-AY21)*#REF!) -> #REF! | BC21: =+BA21+BB21 -> 0 | BD21: =+BC21-BF21 -> 0 | BE21: =((BC21-BD21)*#REF!) -> #REF! | BH21: =+BF21+BG21 -> 0 | BI21: =+BH21-BK21 -> 0 | BJ21: =((BH21-BI21)*#REF!) -> #REF!
